Workbook

Sheet legacy_hidden_sheet_1

Sheet vaccines
A1: id | B1: code_name | C1: product_characteristics_link_primary_field_for_version_1 | D1: short_name | E1: long_name | F1: manufacturer | G1: in_use_in_Russia | H1: comment_to_show | I1: comment_to_show_wo_html | J1: dosage | K1: creation_date | L1: update_date | M1: OKhLP_specialists_link | N1: laypeople_leaflet_GRLS_link | O1: laypeople_leaflet_OKhLP_link | P1: GRLS_instruction_link | Q1: legacy_links
A2: 1 | B2: BCG_Microgen | C2: https://grls.rosminzdrav.ru/Grls_View_v2.aspx?routingGuid=9f91626d-1063-4ea5-9346-800cc6ef9b44 | D2: БЦЖ (Микроген) | E2: Вакцина туберкулезная (БЦЖ) | F2: Микроген | G2: in use | H2: <p>Используется в двух случаях: <ol><li>на тех территориях, где показатель заболеваемости туберкулеза превышает 80&nbsp;случаев на 100&nbsp;000&nbsp;населения;</li> <li>если в окружении новорожденного есть больной туберкулезом.</li></ol></p> | I2: Используется в двух случаях: 1. на тех территориях, где показатель заболеваемости туберкулеза превышает 80 случаев на 100 000 населения; 2. если в окружении новорожденного есть больной туберкулезом. | J2: =0.05 -> 0.05 | K2: 44712 | L2: 45689 | M2: есть | N2: https://grls.rosminzdrav.ru/Grls_View_v2.aspx?routingGuid=9f91626d-1063-4ea5-9346-800cc6ef9b44 | O2: есть | P2: https://grls.rosminzdrav.ru/Grls_View_v2.aspx?routingGuid=e175064d-f010-42d9-bfca-0b186e7cb1d7 | Q2: http://grls.rosminzdrav.ru/Grls_View_v2.aspx?routingGuid=f4d664a2-1579-4fe1-a208-c61795ed1ce9&t= https://grls.rosminzdrav.ru/Grls_View_v2.aspx?routingGuid=580694c3-d27d-4aa9-900d-0437dc6119ca https://grls.rosminzdrav.ru/Grls_View_v2.aspx?routingGuid=e175064d-f010-42d9-bfca-0b186e7cb1d7 https://lk.regmed.ru/Register/GetPDFfromDA?ID=1597322951 https://lk.regmed.ru/Register/GetPDFfromDA?ID=1597323001
A3: 2 | B3: BCG_M_Microgen | C3: https://grls.rosminzdrav.ru/Grls_View_v2.aspx?routingGuid=115ba81b-7cb9-4737-9e63-163458ef9d0b | D3: БЦЖ-М (Микроген) | E3: Вакцина туберкулезная для щадящей первичной иммунизации (БЦЖ-М) | F3: Микроген | G3: in use | H3: <p>Используется по умолчанию для вакцинации детей против туберкулеза. Однако на территориях с повышенной заболеваемостью туберкулезом, а также если в окружении новорожденного есть больной туберкулезом, используется другая вакцина — "БЦЖ".</p> | I3: Используется по умолчанию для вакцинации детей против туберкулеза. Однако на территориях с повышенной заболеваемостью туберкулезом, а также если в окружении новорожденного есть больной туберкулезом, используется другая вакцина — "БЦЖ". | J3: =0.025 -> 0.025 | K3: 44712 | L3: 45689 | M3: есть | N3: https://grls.rosminzdrav.ru/Grls_View_v2.aspx?routingGuid=115ba81b-7cb9-4737-9e63-163458ef9d0b | O3: есть | P3: https://grls.rosminzdrav.ru/Grls_View_v2.aspx?routingGuid=84b15383-df1c-4cb1-a2bb-287483fe9800 | Q3: http://grls.rosminzdrav.ru/Grls_View_v2.aspx?routingGuid=c4592056-f001-476c-9fcf-8f64bc5ec53b&t= https://grls.rosminzdrav.ru/Grls_View_v2.aspx?routingGuid=42231e5b-155e-451f-9f13-d2990507b30c https://grls.rosminzdrav.ru/Grls_View_v2.aspx?routingGuid=84b15383-df1c-4cb1-a2bb-287483fe9800 https://lk.regmed.ru/Register/GetPDFfromDA?ID=1597318981 https://lk.regmed.ru/Register/GetPDFfromDA?ID=1597319151
A4: 3 | B4: BCG_Gamaleya | C4: https://grls.rosminzdrav.ru/Grls_View_v2.aspx?routingGuid=4215760f-875d-476b-a9b6-af2e398c3025 | D4: БЦЖ (Гамалеи) | E4: Вакцина туберкулезная (БЦЖ) | F4: НИЦЭМ им. Н.Ф. Гамалеи | G4: in use | H4: <p>Используется в двух случаях: <ol><li>на тех территориях, где показатель заболеваемости туберкулеза превышает 80&nbsp;случаев на 100&nbsp;000&nbsp;населения;</li> <li>если в окружении новорожденного есть больной туберкулезом.</li></ol></p> | I4: Используется в двух случаях: 1. на тех территориях, где показатель заболеваемости туберкулеза превышает 80 случаев на 100 000 населения; 2. если в окружении новорожденного есть больной туберкулезом. | J4: =0.05 -> 0.05 | K4: 44712 | L4: 45801 | M4: есть | N4: https://grls.rosminzdrav.ru/Grls_View_v2.aspx?routingGuid=4215760f-875d-476b-a9b6-af2e398c3025 | O4: есть | P4: https://grls.rosminzdrav.ru/Grls_View_v2.aspx?routingGuid=9197ac42-596c-4696-829a-f39b4433e1ba | Q4: http://grls.rosminzdrav.ru/Grls_View_v2.aspx?routingGuid=43b8e297-04e6-46a8-9d65-f7f656dfcafc&t= https://grls.rosminzdrav.ru/Grls_View_v2.aspx?routingGuid=9197ac42-596c-4696-829a-f39b4433e1ba
A5: 4 | B5: BCG_M_Gamaleya | C5: https://grls.rosminzdrav.ru/Grls_View_v2.aspx?routingGuid=30fc01db-b288-495f-9e55-e1dd798d18a9 | D5: БЦЖ-М (Гамалеи) | E5: Вакцина туберкулезная для щадящей первичной иммунизации (БЦЖ-М) | F5: НИЦЭМ им. Н.Ф. Гамалеи | G5: in use | H5: <p>Используется по умолчанию для вакцинации детей против туберкулеза. Однако на территориях с повышенной заболеваемостью туберкулезом, а также если в окружении новорожденного есть больной туберкулезом, используется другая вакцина — "БЦЖ".</p> | I5: Используется по умолчанию для вакцинации детей против туберкулеза. Однако на территориях с повышенной заболеваемостью туберкулезом, а также если в окружении новорожденного есть больной туберкулезом, используется другая вакцина — "БЦЖ". | J5: =0.025 -> 0.025 | K5: 44712 | L5: 45818 | M5: есть | N5: https://grls.rosminzdrav.ru/Grls_View_v2.aspx?routingGuid=30fc01db-b288-495f-9e55-e1dd798d18a9 | O5: есть | P5: https://grls.rosminzdrav.ru/Grls_View_v2.aspx?routingGuid=221f440c-110f-4587-8edb-bc7559e9b891 | Q5: http://grls.rosminzdrav.ru/Grls_View_v2.aspx?routingGuid=d9b7a224-4ea9-4e72-9147-51b294e89dc3&t= https://grls.rosminzdrav.ru/Grls_View_v2.aspx?routingGuid=221f440c-110f-4587-8edb-bc7559e9b891
A6: 5 | B6: Infanrix | C6: https://grls.rosminzdrav.ru/Grls_View_v2.aspx?routingGuid=60b8bad6-1fec-492d-a07c-25eee3daa0b5 | D6: Инфанрикс | E6: Инфанрикс® (Вакцина для профилактики дифтерии, столбняка, коклюша (бесклеточная) трехкомпонентная адсорбированная жидкая) | F6: GSK | G6: not in use | H6: <p>DTaP, бесклеточный коклюшный компонент</p> | I6: DTaP, бесклеточный коклюшный компонент | J6: =0.5 -> 0.5 | K6: 44712 | L6: 45689 | M6: есть | N6: нет | O6: есть | P6: https://grls.rosminzdrav.ru/Grls_View_v2.aspx?routingGuid=60b8bad6-1fec-492d-a07c-25eee3daa0b5 | Q6: http://grls.rosminzdrav.ru/Grls_View_v2.aspx?routingGuid=5d56b9eb-b9a5-4bd5-b6cc-ff7f975b513b&t= https://grls.rosminzdrav.ru/Grls_View_v2.aspx?routingGuid=58af8725-f1f7-4c7e-8b50-f3f15e82f83f https://grls.rosminzdrav.ru/Grls_View_v2.aspx?routingGuid=415bcf4b-21de-45a5-b2b4-60dc3b1dce77
A7: 6 | B7: AKDS_Microgen | C7: https://grls.rosminzdrav.ru/Grls_View_v2.aspx?routingGuid=73faea00-ddd0-427e-9f40-49dfea9a2470 | D7: АКДС (Микроген) | E7: Вакцина коклюшно-дифтерийно-столбнячная адсорбированная (АКДС-вакцина) | F7: Микроген | G7: in use | H7: <p>DTaP, цельноклеточный коклюшный компонент</p> | I7: DTaP, цельноклеточный коклюшный компонент | J7: =0.5 -> 0.5 | K7: 44712 | L7: 45689 | M7: есть | N7: https://grls.rosminzdrav.ru/Grls_View_v2.aspx?routingGuid=73faea00-ddd0-427e-9f40-49dfea9a2470 | O7: есть | P7: https://grls.rosminzdrav.ru/Grls_View_v2.aspx?routingGuid=e6156693-4103-4342-8849-ac022e006944 | Q7: http://grls.rosminzdrav.ru/Grls_View_v2.aspx?routingGuid=a670767c-43c3 – 4823-8c12-311809975160&t= https://grls.rosminzdrav.ru/Grls_View_v2.aspx?routingGuid=eaf85871-f010-44dc-9405-8624e77e3499 https://grls.rosminzdrav.ru/Grls_View_v2.aspx?routingGuid=e6156693-4103-4342-8849-ac022e006944 https://lk.regmed.ru/Register/GetPDFfromDA?ID=1587927891 https://lk.regmed.ru/Register/GetPDFfromDA?ID=1587927901
A8: 7 | B8: AKDS_Biomed | C8: https://grls.rosminzdrav.ru/Grls_View_v2.aspx?routingGuid=aba4f9bd-407e-42a8-a32c-1105beece2f6 | D8: АКДС (Биомед) | E8: Вакцина коклюшно-дифтерийно-столбнячная адсорбированная (АКДС-вакцина) | F8: Биомед | G8: in use | H8: <p>DTaP, цельноклеточный коклюшный компонент</p> | I8: DTaP, цельноклеточный коклюшный компонент | J8: =0.5 -> 0.5 | K8: 44712 | L8: 45079 | M8: нет | N8: нет | O8: нет | P8: https://grls.rosminzdrav.ru/Grls_View_v2.aspx?routingGuid=aba4f9bd-407e-42a8-a32c-1105beece2f6
A9: 8 | B9: Bubo_kok | C9: https://grls.rosminzdrav.ru/Grls_View_v2.aspx?routingGuid=81b39c46-e795-4993-b85b-0cf51e164f6b | D9: Бубо-Кок | E9: Бубо®-Кок | F9: Комбиотех | G9: not in use | J9: =0.5 -> 0.5 | K9: 44712 | L9: 44712 | M9: нет | N9: нет | O9: нет | P9: https://grls.rosminzdrav.ru/Grls_View_v2.aspx?routingGuid=81b39c46-e795-4993-b85b-0cf51e164f6b
A10: 9 | B10: Pentaxim | C10: https://grls.rosminzdrav.ru/Grls_View_v2.aspx?routingGuid=04b887e5-95d7-44df-beaa-a539fe956444 | D10: Пентаксим | E10: Пентаксим® (вакцина для профилактики дифтерии и столбняка адсорбированная, коклюша ацеллюлярная, полиомиелита инактивированная и инфекций, вызываемых Haemophilus influenzae тип b, конъюгированная) | F10: Sanofi Pasteur | G10: in use | H10: <p>DTaP-IPV-Hib, бесклеточный коклюшный компонент</p> | I10: DTaP-IPV-Hib, бесклеточный коклюшный компонент | J10: =0.5 -> 0.5 | K10: 44712 | L10: 46204 | M10: есть | N10: https://grls.rosminzdrav.ru/Grls_View_v2.aspx?routingGuid=04b887e5-95d7-44df-beaa-a539fe956444 | O10: есть | P10: https://grls.rosminzdrav.ru/Grls_View_v2.aspx?routingGuid=fa23fbae-fb1a-45b2-8191-2db254575e44 | Q10: http://grls.rosminzdrav.ru/Grls_View_v2.aspx?routingGuid=f43b3011-7633 – 434e-a703-3e18238e9b83&t= https://grls.rosminzdrav.ru/Grls_View_v2.aspx?routingGuid=4d5a75ea-7318-4f8a-8614-2188f4327bdb&t= https://grls.rosminzdrav.ru/Grls_View_v2.aspx?routingGuid=8289a09f-0328-4db3-9276-2022b87fed33 https://grls.rosminzdrav.ru/Grls_View_v2.aspx?routingGuid=fa23fbae-fb1a-45b2-8191-2db254575e44 https://lk.regmed.ru/Register/GetPDFfromDA?ID=1513980681 https://grls.rosminzdrav.ru/Grls_View_v2.aspx?routingGuid=b2790880-bd07-4709-bcc8-484689f1439b https://lk.regmed.ru/Register/GetPDFfromDA?ID=1574041341 https://lk.regmed.ru/Register/GetPDFfromDA?ID=1582784751 https://lk.regmed.ru/Register/GetPDFfromDA?ID=1582784721 https://grls.rosminzdrav.ru/Grls_View_v2.aspx?routingGuid=023a461f-a6cb-488f-8489-6afbcdaac988 https://grls.rosminzdrav.ru/Grls_View_v2.aspx?routingGuid=c5882f45-fe9f-4981-9d00-2a4c650d1d69
A11: 10 | B11: Infanrix_Hexa | C11: https://grls.rosminzdrav.ru/Grls_View_v2.aspx?routingGuid=f9454b06-083d-4c13-8eda-e54a19450d13 | D11: Инфанрикс Гекса | E11: Инфанрикс® Гекса (Вакцина для профилактики дифтерии, столбняка, коклюша (бесклеточная), полиомиелита (инактивированная), гепатита B комбинированная, адсорбированная в комплекте с вакциной для профилактики инфекции, вызываемой Haemophilus influenzae тип b конъюгированной, адсорбированной) | F11: GSK | G11: in use | H11: <p>DTaP-IPV-Hib-HepB, бесклеточный коклюшный компонент</p> | I11: DTaP-IPV-Hib-HepB, бесклеточный коклюшный компонент | J11: =0.5 -> 0.5 | K11: 44712 | L11: 46000 | M11: есть | N11: https://grls.rosminzdrav.ru/Grls_View_v2.aspx?routingGuid=f9454b06-083d-4c13-8eda-e54a19450d13 | O11: есть | P11: https://grls.rosminzdrav.ru/Grls_View_v2.aspx?routingGuid=4b6927fa-e480-44a7-b945-557299500fe8 | Q11: http://grls.rosminzdrav.ru/Grls_View_v2.aspx?routingGuid=5aba1c6d-00b7-484e-b79c-ad45273f4575&t= https://grls.rosminzdrav.ru/Grls_View_v2.aspx?routingGuid=1a3ae12c-6484-4823-a535-8a689832cc91&t= https://grls.rosminzdrav.ru/Grls_View_v2.aspx?routingGuid=d9b8e111-d7b5-4d26-bfb7-cabd995d0470 https://grls.rosminzdrav.ru/Grls_View_v2.aspx?routingGuid=8e26d23e-07b5-4826-b6e2-686cce4141a8 https://grls.rosminzdrav.ru/Grls_View_v2.aspx?routingGuid=3a8d0e82-1e71-4ef0-b0c4-10350ec87f9a
A12: 11 | B12: Bubo_M | C12: https://grls.rosminzdrav.ru/Grls_View_v2.aspx?routingGuid=0b7d30f1-b40f-453c-9c7b-800a072aa409 | D12: Бубо-М | E12: Бубо®-М (Вакцина комбинированная гепатита B и анатоксина дифтерийно-столбнячного с уменьшенным содержанием антигенов адсорбированная жидкая) | F12: Комбиотех | G12: not in use | J12: =0.5 -> 0.5 | K12: 44712 | L12: 46188 | M12: есть | N12: нет | O12: есть | P12: https://grls.rosminzdrav.ru/Grls_View_v2.aspx?routingGuid=0b7d30f1-b40f-453c-9c7b-800a072aa409 | Q12: https://grls.rosminzdrav.ru/Grls_View_v2.aspx?routingGuid=d4d36459-a495-4769-bf77-558ba99330b1
A13: 12 | B13: AD_M_Microgen | C13: https://grls.rosminzdrav.ru/Grls_View_v2.aspx?routingGuid=fa42329f-9433-4dc6-af8a-f811be13fb87 | D13: АД-М (Микроген) | E13: Анатоксин дифтерийный очищенный адсорбированный с уменьшенным содержанием антигена жидкий (АД-М-анатоксин) | F13: Микроген | G13: in use | J13: =0.5 -> 0.5 | K13: 44712 | L13: 45689 | M13: https://lk.regmed.ru/Register/GetPDFfromDAToken?Token=9916a334-02fd-4f23-ad64-c996916ac2d6 | N13: https://grls.rosminzdrav.ru/Grls_View_v2.aspx?routingGuid=fa42329f-9433-4dc6-af8a-f811be13fb87 | O13: https://lk.regmed.ru/Register/GetPDFfromDAToken?Token=22df29cf-dc92-4628-a24c-edf2e8b2b256 | P13: https://grls.rosminzdrav.ru/Grls_View_v2.aspx?routingGuid=6e48dbe9-c71e-4694-b7ac-47a70cf6b097 | Q13: http://grls.rosminzdrav.ru/Grls_View_v2.aspx?routingGuid=2a2e60b9-cc49-4bc2-9f7f-5766163a5610&t= https://grls.rosminzdrav.ru/Grls_View_v2.aspx?routingGuid=be7e45b4-ee7c-4ffc-b4fd-6b8e48edfbe3 https://grls.rosminzdrav.ru/Grls_View_v2.aspx?routingGuid=6e48dbe9-c71e-4694-b7ac-47a70cf6b097 https://lk.regmed.ru/Register/GetPDFfromDA?ID=1601683231 https://lk.regmed.ru/Register/GetPDFfromDA?ID=1601683241
A14: 13 | B14: ADS_Microgen | C14: https://grls.rosminzdrav.ru/Grls_View_v2.aspx?routingGuid=82af2230-6ada-4cb2-a263-0a2c1f841be2 | D14: АДС (Микроген) | E14: Анатоксин дифтерийно-столбнячный очищенный адсорбированный жидкий (АДС-анатоксин) | F14: Микроген | G14: in use | J14: =0.5 -> 0.5 | K14: 44712 | L14: 45689 | M14: https://lk.regmed.ru/Register/GetPDFfromDAToken?Token=ff0cddac-c2c3-4fac-84e2-d026f4f71869 | N14: https://grls.rosminzdrav.ru/Grls_View_v2.aspx?routingGuid=82af2230-6ada-4cb2-a263-0a2c1f841be2 | O14: https://lk.regmed.ru/Register/GetPDFfromDAToken?Token=9a6142ea-2a03-4b1a-9dbb-31db8de71e87 | P14: https://grls.rosminzdrav.ru/Grls_View_v2.aspx?routingGuid=263b30af-486c-42e0-911a-2a5ed131f20b | Q14: http://grls.rosminzdrav.ru/Grls_View_v2.aspx?routingGuid=56e77eb8-534a-44be-afd0-061fb8ec4621&t= https://grls.rosminzdrav.ru/Grls_View_v2.aspx?routingGuid=2a7cde6e-0f3e-447e-9619-585de96a0f74 https://grls.rosminzdrav.ru/Grls_View_v2.aspx?routingGuid=263b30af-486c-42e0-911a-2a5ed131f20b https://lk.regmed.ru/Register/GetPDFfromDA?ID=1605321651 https://lk.regmed.ru/Register/GetPDFfromDA?ID=1605321641
A15: 14 | B15: ADS_M_Microgen | C15: https://grls.rosminzdrav.ru/Grls_View_v2.aspx?routingGuid=7901c857-1397-49d2-9a93-f8c171091efa | D15: АДС-М (Микроген) | E15: Анатоксин дифтерийно-столбнячный очищенный адсорбированный с уменьшенным содержанием антигенов жидкий (АДС-М-анатоксин) | F15: Микроген | G15: in use | J15: =0.5 -> 0.5 | K15: 44712 | L15: 45861 | M15: https://lk.regmed.ru/Register/GetPDFfromDAToken?Token=67df064e-3139-49b6-917f-a5131fbd35d6 | N15: https://grls.rosminzdrav.ru/Grls_View_v2.aspx?routingGuid=7901c857-1397-49d2-9a93-f8c171091efa | O15: https://lk.regmed.ru/Register/GetPDFfromDAToken?Token=8e7de8c8-45c1-4c8d-8449-0c0d2af1e327 | P15: https://grls.rosminzdrav.ru/Grls_View_v2.aspx?routingGuid=6aefbaea-b7c4-49fe-b6a2-0d376c18f14a | Q15: http://grls.rosminzdrav.ru/Grls_View_v2.aspx?routingGuid=f7b0a096-adc5-4d00-9845-688629c81df0&t= https://grls.rosminzdrav.ru/Grls_View_v2.aspx?routingGuid=25f82e77-7060-400f-9bbb-141130ec982a&t= https://grls.rosminzdrav.ru/Grls_View_v2.aspx?routingGuid=6aefbaea-b7c4-49fe-b6a2-0d376c18f14a https://lk.regmed.ru/Register/GetPDFfromDA?ID=1600526521 https://lk.regmed.ru/Register/GetPDFfromDA?ID=1600526511 https://grls.rosminzdrav.ru/Grls_View_v2.aspx?routingGuid=95537b39-97ee-4255-9697-68976985653e
A16: 15 | B16: ADS_M_Biomed | C16: https://grls.rosminzdrav.ru/Grls_View_v2.aspx?routingGuid=795940d7 – 9c11-423c-98fe-44a1d739a593 | D16: АДС-М (Биомед) | E16: Анатоксин дифтерийно-столбнячный очищенный адсорбированный с уменьшенным содержанием антигенов жидкий (АДС-М анатоксин) | F16: Биомед | G16: in use | J16: =0.5 -> 0.5 | K16: 44712 | L16: 44712 | M16: нет | N16: нет | O16: нет | P16: https://grls.rosminzdrav.ru/Grls_View_v2.aspx?routingGuid=795940d7-9c11-423c-98fe-44a1d739a593
A17: 16 | B17: Adacel | C17: https://grls.rosminzdrav.ru/Grls_View_v2.aspx?routingGuid=d8627a3c-16a5-46d0-b31f-e60eb2448d80 | D17: Адасель | E17: АДАСЕЛЬ® [Вакцина для профилактики дифтерии (с уменьшенным содержанием антигена), коклюша (с уменьшенным содержанием антигена, бесклеточная) и столбняка, комбинированная, адсорбированная] | F17: Санофи Пастер Лимитед | G17: in use | H17: <p>Tdap, сниженное содержание дифтерийного и коклюшного компонента, бесклеточный коклюшный компонент</p> | I17: Tdap, сниженное содержание дифтерийного и коклюшного компонента, бесклеточный коклюшный компонент | J17: =0.5 -> 0.5 | K17: 44712 | L17: 45689 | M17: https://lk.regmed.ru/Register/GetPDFfromDAToken?Token=7fabfdf2-4fe8-448e-859f-9a4b20cc3213 | N17: https://grls.rosminzdrav.ru/Grls_View_v2.aspx?routingGuid=d8627a3c-16a5-46d0-b31f-e60eb2448d80 | O17: https://lk.regmed.ru/Register/GetPDFfromDAToken?Token=64e50f3b-676a-4ffd-a308-008f4019c7c0 | P17: https://grls.rosminzdrav.ru/Grls_View_v2.aspx?routingGuid=375ef2f9-abab-464c-b1b3-b993bc8f42ec | Q17: http://grls.rosminzdrav.ru/Grls_View_v2.aspx?routingGuid=6e2aecff-8338-4266-8505-8b8c9b01801a&t= https://grls.rosminzdrav.ru/Grls_View_v2.aspx?routingGuid=7eeca2fc-ee22-43f1-a33e-01b127cb9cce&t= https://grls.rosminzdrav.ru/Grls_View_v2.aspx?routingGuid=95654753-d6d2-4485-8c56-7f29dbeace86 https://grls.rosminzdrav.ru/Grls_View_v2.aspx?routingGuid=375ef2f9-abab-464c-b1b3-b993bc8f42ec https://lk.regmed.ru/Register/GetPDFfromDA?ID=1555257271 https://lk.regmed.ru/Register/GetPDFfromDA?ID=1592320751 https://lk.regmed.ru/Register/GetPDFfromDA?ID=1592320761
A18: 17 | B18: Algavac_M | C18: https://grls.rosminzdrav.ru/Grls_View_v2.aspx?routingGuid=2bf12380-3a71-4642-a9a3-ef0e4ca9b815 | D18: Альгавак М | E18: АЛЬГАВАК® М | G18: in use | K18: 44712 | L18: 45715 | M18: нет | N18: нет | O18: нет | P18: https://grls.rosminzdrav.ru/Grls_View_v2.aspx?routingGuid=2bf12380-3a71-4642-a9a3-ef0e4ca9b815 | Q18: http://grls.rosminzdrav.ru/Grls_View_v2.aspx?routingGuid=19f151f4-39f1-4518-bdad-6c70489cb7db&t= https://grls.rosminzdrav.ru/Grls_View_v2.aspx?routingGuid=d5b58794-3b91-45d1-84ee-df1f0ee83ea6
A19: 18 | B19: Algavac | C19: https://grls.rosminzdrav.ru/Grls_View_v2.aspx?routingGuid=4f6d874c-7745-4c6b-8c90-228a1f2f3484 | D19: Альгавак | E19: АЛЬГАВАК® | G19: not in use | H19: <p>Вакцину АЛЬГАВАК можно использовать для ревакцинации в тех случаях, когда предыдущая вакцинация осуществлялась другими инактивированными вакцинами для профилактики гепатита А.</p> | I19: Вакцину АЛЬГАВАК можно использовать для ревакцинации в тех случаях, когда предыдущая вакцинация осуществлялась другими инактивированными вакцинами для профилактики гепатита А. | K19: 44712 | L19: 46188 | M19: есть | N19: нет | O19: есть | P19: https://grls.rosminzdrav.ru/Grls_View_v2.aspx?routingGuid=4f6d874c-7745-4c6b-8c90-228a1f2f3484 | Q19: https://grls.rosminzdrav.ru/Grls_View_v2.aspx?routingGuid=a282addd-c0aa-4540-a495-2a96a71e6fbe https://grls.rosminzdrav.ru/Grls_View_v2.aspx?routingGuid=f7a52b5d-5517-4495-b65c-80dd8f948f0c
A20: 19 | B20: Havrix_720 | C20: https://grls.rosminzdrav.ru/Grls_View_v2.aspx?routingGuid=b8dfef4d-a4cf-4d18-9599-1a3fb42864c7 | D20: Хаврикс 720 | E20: Хаврикс® (вакцина против гепатита А инактивированная) | F20: GSK | G20: in use | K20: 44712 | L20: 45689 | M20: https://lk.regmed.ru/Register/GetPDFfromDAToken?Token=6d0a7c06-3859-4f01-8d37-bf8887046a88 | N20: https://grls.rosminzdrav.ru/Grls_View_v2.aspx?routingGuid=b8dfef4d-a4cf-4d18-9599-1a3fb42864c7 | O20: https://lk.regmed.ru/Register/GetPDFfromDAToken?Token=88854c2c-329e-40d6-9464-84468572891b | P20: https://grls.rosminzdrav.ru/Grls_View_v2.aspx?routingGuid=8c19af66-4fb0-474c-a1bf-d60e191504cd | Q20: http://grls.rosminzdrav.ru/Grls_View_v2.aspx?routingGuid=8ecd1f23-ce36-4316-8f63 – 4aa28a61a7e4&t= https://grls.rosminzdrav.ru/Grls_View_v2.aspx?routingGuid=7f9925e4-9dd3 – 46b4-9a72-c4306af33e14&t= https://grls.rosminzdrav.ru/Grls_View_v2.aspx?routingGuid=6cee7e81-acb9-4ae0-8da8-13bc218f9f43 https://grls.rosminzdrav.ru/Grls_View_v2.aspx?routingGuid=8ffa4f17-cffc-4a79-b721-833a058ae522 https://lk.regmed.ru/Register/GetPDFfromDA?ID=1607490831 https://lk.regmed.ru/Register/GetPDFfromDA?ID=1607490821
A21: 20 | B21: Havrix_1440 | C21: https://grls.rosminzdrav.ru/Grls_View_v2.aspx?routingGuid=b8dfef4d-a4cf-4d18-9599-1a3fb42864c7 | D21: Хаврикс 1440 | E21: Хаврикс® (вакцина против гепатита А инактивированная) | F21: GSK | G21: not in use | K21: 44712 | L21: 45689 | M21: https://lk.regmed.ru/Register/GetPDFfromDAToken?Token=6d0a7c06-3859-4f01-8d37-bf8887046a88 | N21: https://grls.rosminzdrav.ru/Grls_View_v2.aspx?routingGuid=b8dfef4d-a4cf-4d18-9599-1a3fb42864c7 | O21: https://lk.regmed.ru/Register/GetPDFfromDAToken?Token=88854c2c-329e-40d6-9464-84468572891b | P21: https://grls.rosminzdrav.ru/Grls_View_v2.aspx?routingGuid=8c19af66-4fb0-474c-a1bf-d60e191504cd | Q21: http://grls.rosminzdrav.ru/Grls_View_v2.aspx?routingGuid=8ecd1f23-ce36-4316-8f63 – 4aa28a61a7e4&t= https://grls.rosminzdrav.ru/Grls_View_v2.aspx?routingGuid=7f9925e4-9dd3 – 46b4-9a72-c4306af33e14&t= https://grls.rosminzdrav.ru/Grls_View_v2.aspx?routingGuid=6cee7e81-acb9-4ae0-8da8-13bc218f9f43 https://grls.rosminzdrav.ru/Grls_View_v2.aspx?routingGuid=8ffa4f17-cffc-4a79-b721-833a058ae522 https://lk.regmed.ru/Register/GetPDFfromDA?ID=1607490831 https://lk.regmed.ru/Register/GetPDFfromDA?ID=1607490821 https://lk.regmed.ru/Register/GetPDFfromDA?ID=1607490821
A22: 21 | B22: Avaxim_80 | C22: https://grls.rosminzdrav.ru/Grls_View_v2.aspx?routingGuid=0814c0aa-66c2-4566-a774-02de4c45b6ac | D22: Аваксим 80 | E22: Аваксим 80 (вакцина для профилактики гепатита A инактивированная, адсорбированная) | G22: not in use | K22: 44712 | L22: 44916 | M22: нет | N22: нет | O22: нет | P22: https://grls.rosminzdrav.ru/Grls_View_v2.aspx?routingGuid=0814c0aa-66c2-4566-a774-02de4c45b6ac | Q22: http://grls.rosminzdrav.ru/Grls_View_v2.aspx?routingGuid=3a8088d9-7d7f-445f-a8e4-a1bab7a809ad&t= https://grls.rosminzdrav.ru/Grls_View_v2.aspx?routingGuid=78ff9266-b5f3 – 490a-a1b8-27301443480a&t=
A23: 22 | B23: Avaxim_160 | C23: https://grls.rosminzdrav.ru/Grls_View_v2.aspx?routingGuid=658e07cb-fcb9-412f-9392-b9e9e21a6343 | D23: Аваксим 160 | E23: Аваксим 160 (вакцина для профилактики гепатита A инактивированная, адсорбированная) | G23: not in use | K23: 44712 | L23: 44916 | M23: нет | N23: нет | O23: нет | P23: https://grls.rosminzdrav.ru/Grls_View_v2.aspx?routingGuid=658e07cb-fcb9-412f-9392-b9e9e21a6343 | Q23: http://grls.rosminzdrav.ru/Grls_View_v2.aspx?routingGuid=0e797243-3326-40c5-91d4-3790146525e4&t= https://grls.rosminzdrav.ru/Grls_View_v2.aspx?routingGuid=5209bb3a-760a-415a-8697-652ac260fca5&t=
A24: 23 | B24: Regevac_0_5 | C24: https://grls.rosminzdrav.ru/Grls_View_v2.aspx?routingGuid=ec6e3b51-e76b-4abf-99cf-7c02bab06091 | D24: Регевак детский | E24: Регевак® В (Вакцина против гепатита В, рекомбинантная дрожжевая жидкая) | G24: in use | K24: 44712 | L24: 45988 | M24: есть | N24: нет | O24: есть | P24: https://grls.rosminzdrav.ru/Grls_View_v2.aspx?routingGuid=ec6e3b51-e76b-4abf-99cf-7c02bab06091 | Q24: http://grls.rosminzdrav.ru/Grls_View_v2.aspx?routingGuid=accc9e6e-21d3 – 4b43-8eb4-65d0bf807a6a&t= https://grls.rosminzdrav.ru/Grls_View_v2.aspx?routingGuid=7bf6a88b-0ee8-48d7-afe3-7585739a9aaf https://grls.rosminzdrav.ru/Grls_View_v2.aspx?routingGuid=7b2a598f-1146-475f-9678-bf4c14e2523a
A25: 24 | B25: HepB_Combiotech_0_5 | C25: https://grls.rosminzdrav.ru/Grls_View_v2.aspx?routingGuid=0cc60fe9-635e-4134-80d2-59a7787e33fb | D25: гепатита B (Комбиотех) детская | E25: Вакцина гепатита В рекомбинантная дрожжевая | F25: Комбиотех | G25: in use | H25: <p>Препарат выпускается в виде «взрослой» и «детской» вакцины с консервантом и без консерванта.</p> | I25: Препарат выпускается в виде «взрослой» и «детской» вакцины с консервантом и без консерванта. | K25: 44712 | L25: 46130 | M25: есть | N25: нет | O25: нет | P25: https://grls.rosminzdrav.ru/Grls_View_v2.aspx?routingGuid=0cc60fe9-635e-4134-80d2-59a7787e33fb | Q25: https://grls.rosminzdrav.ru/Grls_View_v2.aspx?routingGuid=3059b036-5e60-42ed-b26c-7eb6d5d06406
A26: 25 | B26: Euvax_B_0_5 | C26: https://grls.rosminzdrav.ru/Grls_View_v2.aspx?routingGuid=0d28b2ad-18b2-4e7a-8c27-436c0feea6d4 | D26: Эувакс В детский | E26: Эувакс В (вакцина для профилактики гепатита B рекомбинантная) | G26: not in use | K26: 44712 | L26: 44712 | M26: нет | N26: нет | O26: нет | P26: https://grls.rosminzdrav.ru/Grls_View_v2.aspx?routingGuid=0d28b2ad-18b2-4e7a-8c27-436c0feea6d4 | Q26: https://grls.rosminzdrav.ru/Grls_View_v2.aspx?routingGuid=0c704154-cba0-4019-ad47-535acfcd840c
A27: 26 | B27: Euvax_B_1_0 | C27: https://grls.rosminzdrav.ru/Grls_View_v2.aspx?routingGuid=0d28b2ad-18b2-4e7a-8c27-436c0feea6d4 | D27: Эувакс В взрослый | E27: Эувакс В (вакцина для профилактики гепатита B рекомбинантная) | G27: not in use | K27: 44712 | L27: 44712 | M27: нет | N27: нет | O27: нет | P27: https://grls.rosminzdrav.ru/Grls_View_v2.aspx?routingGuid=0d28b2ad-18b2-4e7a-8c27-436c0feea6d4 | Q27: https://grls.rosminzdrav.ru/Grls_View_v2.aspx?routingGuid=0c704154-cba0-4019-ad47-535acfcd840c
A28: 27 | B28: Cervarix | C28: https://grls.rosminzdrav.ru/Grls_View_v2.aspx?routingGuid=eb109c11-f04c-4753-b278-73a5bd064e47 | D28: Церварикс | E28: Церварикс® | G28: in use | K28: 44712 | L28: 45689 | M28: https://lk.regmed.ru/Register/GetPDFfromDAToken?Token=f88d9e07-3794-4fde-9c2d-fd91c377cc95 | N28: https://grls.rosminzdrav.ru/Grls_View_v2.aspx?routingGuid=eb109c11-f04c-4753-b278-73a5bd064e47 | O28: https://lk.regmed.ru/Register/GetPDFfromDAToken?Token=a5276048-6e32-4f08-9d02-266d9f69b4db | P28: https://grls.rosminzdrav.ru/Grls_View_v2.aspx?routingGuid=74a77c48-c131-41c4-ab9d-88f8daa7fa64 | Q28: http://grls.rosminzdrav.ru/Grls_View_v2.aspx?routingGuid=f1674482-805b-467b-896f-f78e3c14cba4&t= https://grls.rosminzdrav.ru/Grls_View_v2.aspx?routingGuid=ad735aab-e490-4da0-a3d9-0cec0766c5ca&t= https://grls.rosminzdrav.ru/Grls_View_v2.aspx?routingGuid=2978c96b-a743 – 462b-8c08-0a3d26589799 https://lk.regmed.ru/Register/GetPDFfromDA?ID=1611660161 https://lk.regmed.ru/Register/GetPDFfromDA?ID=1611660121
A29: 28 | B29: Gardasil_4 | C29: https://grls.rosminzdrav.ru/Grls_View_v2.aspx?routingGuid=2ae3187f-3553-4a0f-953d-db66a9c16d23 | D29: Гардасил 4 | E29: Гардасил® | F29: MSD | G29: in use | H29: <p>4-валентная</p> | I29: 4-валентная | J29: =0.5 -> 0.5 | K29: 44712 | L29: 45689 | M29: https://lk.regmed.ru/Register/GetPDFfromDAToken?Token=ba26e648-28b3-4eac-b578-0748c8e03c4e | N29: нет | O29: https://lk.regmed.ru/Register/GetPDFfromDAToken?Token=0b4492da-8526-4af7-a136-8dc82478f429 | P29: https://grls.rosminzdrav.ru/Grls_View_v2.aspx?routingGuid=2ae3187f-3553-4a0f-953d-db66a9c16d23 | Q29: https://grls.rosminzdrav.ru/Grls_View_v2.aspx?routingGuid=aa002533-365b-40c6-b369-8384878dcd93&t= https://grls.rosminzdrav.ru/Grls_View_v2.aspx?routingGuid=2bec1ede-4863 – 4d77-abb6-4e68d781b2e4&t= https://grls.rosminzdrav.ru/Grls_View_v2.aspx?routingGuid=4d6605d8-b4e5-43b2-8c81-ef86901d93fd https://grls.rosminzdrav.ru/Grls_View_v2.aspx?routingGuid=764b9dc3-6936-4f27-b568-bf9afd87abfc https://lk.regmed.ru/Register/GetPDFfromDA?ID=1575625191 https://lk.regmed.ru/Register/GetPDFfromDA?ID=1575625171 https://grls.rosminzdrav.ru/Grls_View_v2.aspx?routingGuid=764b9dc3-6936-4f27-b568-bf9afd87abfc
A30: 29 | B30: Sputnik | C30: https://grls.rosminzdrav.ru/Grls_View_v2.aspx?routingGuid=579be5e3-09cf-46b4-8238-f3087cd4e808 | D30: Спутник V | E30: Гам-КОВИД-Вак Комбинированная векторная вакцина для профилактики коронавирусной инфекции, вызываемой вирусом SARS-CoV-2 | F30: НИЦЭМ им. Н.Ф. Гамалеи | G30: in use | J30: =0.5 -> 0.5 | K30: 44712 | L30: 45923 | M30: https://lk.regmed.ru/Register/GetPDFfromDAToken?Token=dc4e4486-14e8-430b-b506-5364c1e11fe7 | N30: https://grls.rosminzdrav.ru/Grls_View_v2.aspx?routingGuid=579be5e3-09cf-46b4-8238-f3087cd4e808 | O30: https://lk.regmed.ru/Register/GetPDFfromDAToken?Token=3453097f-e598-4860-bd54-aa72f063f2ef | P30: https://grls.rosminzdrav.ru/Grls_View_v2.aspx?routingGuid=85127f3b-11cb-47df-95aa-325127c74955 | Q30: https://grls.rosminzdrav.ru/Grls_View_v2.aspx?routingGuid=d494c688-0bc6-4c30-9e81-23f043ceb43e&t= https://grls.rosminzdrav.ru/Grls_View_v2.aspx?routingGuid=5d7a9ba1-f4ec-4557-ba99-dcab4740067d&t= https://grls.rosminzdrav.ru/Grls_View_v2.aspx?routingGuid=1c3ac13e-0c68-4319-b618-e203985fa74a https://grls.rosminzdrav.ru/Grls_View_v2.aspx?routingGuid=b0900ae9-5b06-4cb2-bdb4-e8a3bec5f6d6
A31: 30 | B31: Sputnik_Lyo | C31: https://grls.rosminzdrav.ru/Grls_View_v2.aspx?routingGuid=ff05de13-f90b-475b-a47c-609c8a0539a7 | D31: Спутник V (лиофилизат) | E31: Гам-КОВИД-Вак-Лио Комбинированная векторная вакцина для профилактики коронавирусной инфекции, вызываемой вирусом SARS-CoV-2 | G31: not in use | K31: 44712 | L31: 44712 | M31: нет | N31: нет | O31: нет | P31: https://grls.rosminzdrav.ru/Grls_View_v2.aspx?routingGuid=ff05de13-f90b-475b-a47c-609c8a0539a7
A32: 31 | B32: EpiVacCorona | C32: https://grls.rosminzdrav.ru/Grls_View_v2.aspx?routingGuid=fd7355d2-abfa-4846-99da-a1c5c6e8991a | D32: ЭпиВакКорона | E32: ЭпиВакКорона Вакцина на основе пептидных антигенов для профилактики COVID-19 | F32: Вектор | G32: not in use | J32: =0.5 -> 0.5 | K32: 44712 | L32: 45078 | M32: нет | N32: нет | O32: нет | P32: https://grls.rosminzdrav.ru/Grls_View_v2.aspx?routingGuid=fd7355d2-abfa-4846-99da-a1c5c6e8991a | Q32: http://grls.rosminzdrav.ru/Grls_View_v2.aspx?routingGuid=d8f07c35 – 7edc-49ab-8647-6b6865449167&t= https://grls.rosminzdrav.ru/Grls_View_v2.aspx?routingGuid=6248c7e9-198f-44e0-9682-5794b677fec3&t= https://grls.rosminzdrav.ru/Grls_View_v2.aspx?routingGuid=34ca6cb0-7450-4f53-8bec-17d2bdf92c2b
A33: 32 | B33: Grippol_Microgen | C33: https://grls.rosminzdrav.ru/Grls_View_v2.aspx?routingGuid=70f8f0f0-7bac-41ec-a36d-51dcd6ebce84 | D33: Гриппол (Микроген) | E33: Гриппол® Вакцина гриппозная тривалентная полимер-субъединичная жидкая | F33: Микроген | G33: not in use | K33: 44712 | L33: 44712 | M33: нет | N33: нет | O33: нет | P33: нет | Q33: https://grls.rosminzdrav.ru/Grls_View_v2.aspx?routingGuid=0ae550bc-37b4-4f2e-bbff-b1a71c00c505
A34: 33 | B34: Grippol_Petrovax | C34: https://grls.rosminzdrav.ru/Grls_View_v2.aspx?routingGuid=ce700a9a-2b35-47e5-a73b-3cf65afee43b | D34: Гриппол (Петровакс) | E34: Гриппол® [Вакцина гриппозная тривалентная полимер-субъединичная жидкая] | F34: Петровакс | G34: not in use | K34: 44712 | L34: 44712 | M34: нет | N34: нет | O34: нет | P34: https://grls.rosminzdrav.ru/Grls_View_v2.aspx?routingGuid=ce700a9a-2b35-47e5-a73b-3cf65afee43b
A35: 34 | B35: Grippol_plus_0_5 | C35: https://grls.rosminzdrav.ru/Grls_View_v2.aspx?routingGuid=907b510e-7f7f-46df-b43a-f6541b9871fc | D35: Гриппол плюс 0,5 мл | E35: Гриппол® плюс [Вакцина гриппозная тривалентная инактивированная полимер-субъединичная] | F35: Петровакс | G35: in use | K35: 44712 | L35: 45689 | M35: https://lk.regmed.ru/Register/GetPDFfromDAToken?Token=8cc54647-279e-4b2f-82d7-b1ed3161d86a | N35: https://grls.rosminzdrav.ru/Grls_View_v2.aspx?routingGuid=907b510e-7f7f-46df-b43a-f6541b9871fc | O35: https://lk.regmed.ru/Register/GetPDFfromDAToken?Token=333cbca5-2931-4145-ba0e-d5b9ee3e74f7 | P35: https://grls.rosminzdrav.ru/Grls_View_v2.aspx?routingGuid=6cb99bc7-105a-4075-a791-8895b32ca394 | Q35: http://grls.rosminzdrav.ru/Grls_View_v2.aspx?routingGuid=e5e46dca-6622-4d3a-a0cd-349a012a5fc0&t= https://grls.rosminzdrav.ru/Grls_View_v2.aspx?routingGuid=85b9ac25-4fe7-4433-8cd8-f0b342dd9cf7&t= https://grls.rosminzdrav.ru/Grls_View_v2.aspx?routingGuid=4427eb1b-4f6c-42f5-9639-cb5f3a09cba2 https://grls.rosminzdrav.ru/Grls_View_v2.aspx?routingGuid=3b219e04-d778-4884-b683-c531afd10243 https://grls.rosminzdrav.ru/InstrImg/2023/09/26/1497492/e385d3ef-3918-4b5f-911b-fd418c787580.pdf https://lk.regmed.ru/Register/GetPDFfromDA?ID=1512826451 https://lk.regmed.ru/Register/GetPDFfromDA?ID=1599002471 https://lk.regmed.ru/Register/GetPDFfromDA?ID=1599002501 https://grls.rosminzdrav.ru/Grls_View_v2.aspx?routingGuid=9f01a261-d030-46db-82a0-3ab09a958a2e https://grls.rosminzdrav.ru/Grls_View_v2.aspx?routingGuid=3b219e04-d778-4884-b683-c531afd10243
A36: 35 | B36: Sovigripp | C36: https://grls.rosminzdrav.ru/Grls_View_v2.aspx?routingGuid=b287b682-550a-418f-8189-05dac16da4ae | D36: Совигрипп | E36: СОВИГРИПП® Вакцина гриппозная инактивированная субъединичная | F36: Микроген | G36: in use | K36: 44712 | L36: 45689 | M36: https://lk.regmed.ru/Register/GetPDFfromDAToken?Token=4d1562e5-05e7-405f-9673-b89a20ffd447 | N36: https://grls.rosminzdrav.ru/Grls_View_v2.aspx?routingGuid=b287b682-550a-418f-8189-05dac16da4ae | O36: https://lk.regmed.ru/Register/GetPDFfromDAToken?Token=068c5473-106f-49bc-a5f7-7ba1b7f020c3 | P36: https://grls.rosminzdrav.ru/Grls_View_v2.aspx?routingGuid=80286849-4848-4b66-a986-a99c8a476964 | Q36: http://grls.rosminzdrav.ru/Grls_View_v2.aspx?routingGuid=52ba41b8-9298-4f53-a5c0-8dedc52494a6&t= https://grls.rosminzdrav.ru/Grls_View_v2.aspx?routingGuid=072a45dd-9eac-44a1-b14d-fa7fffdf4885&t= https://grls.rosminzdrav.ru/Grls_View_v2.aspx?routingGuid=6ed700c7-271c-40a1-814a-0d3f717a24de https://grls.rosminzdrav.ru/Grls_View_v2.aspx?routingGuid=80286849-4848-4b66-a986-a99c8a476964 https://lk.regmed.ru/Register/GetPDFfromDA?ID=1633580161 https://lk.regmed.ru/Register/GetPDFfromDA?ID=1633580151
A37: 36 | B37: Ultrix | C37: https://grls.rosminzdrav.ru/Grls_View_v2.aspx?routingGuid=b90698f2-e111-4450-b82c-5c3ca26a25f5 | D37: Ультрикс | E37: Ультрикс® Вакцина гриппозная инактивированная расщепленная | F37: ФОРТ | G37: not in use | K37: 44712 | L37: 45689 | M37: https://lk.regmed.ru/Register/GetPDFfromDAToken?Token=ebfed185-d787-4d31-8be8-d3cbc95b7794 | N37: https://grls.rosminzdrav.ru/Grls_View_v2.aspx?routingGuid=b90698f2-e111-4450-b82c-5c3ca26a25f5 | O37: https://lk.regmed.ru/Register/GetPDFfromDAToken?Token=030e4140-af45-48dd-b213-76aeb3a23c36 | P37: https://grls.rosminzdrav.ru/Grls_View_v2.aspx?routingGuid=fe89d09a-8d9b-45fa-bb82-740a81904a6d | Q37: http://grls.rosminzdrav.ru/Grls_View_v2.aspx?routingGuid=fb9c24c2-c33a-4920-8361-9997d94b4e68&t= https://grls.rosminzdrav.ru/Grls_View_v2.aspx?routingGuid=fe89d09a-8d9b-45fa-bb82-740a81904a6d https://lk.regmed.ru/Register/GetPDFfromDA?ID=1523760571 https://lk.regmed.ru/Register/GetPDFfromDA?ID=1523760581
A38: 37 | B38: Flu_M | C38: https://grls.rosminzdrav.ru/Grls_View_v2.aspx?routingGuid=e7496b1f-1be9-46a3-b43f-e1c83a5b6cc8 | D38: Флю-М | E38: Флю-М [Вакцина гриппозная инактивированная расщепленная] | F38: СПбНИИВС | G38: in use | K38: 44712 | L38: 46130 | M38: нет | N38: https://grls.rosminzdrav.ru/Grls_View_v2.aspx?routingGuid=e7496b1f-1be9-46a3-b43f-e1c83a5b6cc8 | O38: нет | P38: https://grls.rosminzdrav.ru/Grls_View_v2.aspx?routingGuid=c6301213-2c71-499d-bf27-8fd593484674 | Q38: http://grls.rosminzdrav.ru/Grls_View_v2.aspx?routingGuid=24b95e82-2958-40e4-a4a2-4771c644d37a&t= https://grls.rosminzdrav.ru/Grls_View_v2.aspx?routingGuid=48a4c1e2-75b8-4e93-9354-db9c0f57205c&t= https://grls.rosminzdrav.ru/Grls_View_v2.aspx?routingGuid=6feebd54-4999-44d5-bd49-445441202847 https://grls.rosminzdrav.ru/Grls_View_v2.aspx?routingGuid=dfddbade-1401-4b6d-903d-74fe3c1a2821
A39: 38 | B39: Vaxigrip | C39: https://grls.rosminzdrav.ru/Grls_View_v2.aspx?routingGuid=34537f7c-cc43 – 45ef-bc9a-9820641bf718 | D39: Ваксигрип | E39: Ваксигрип® (инактивированная сплит-вакцина для профилактики гриппа) | G39: not in use | K39: 44712 | L39: 45078 | M39: нет | N39: нет | O39: нет | P39: https://grls.rosminzdrav.ru/Grls_View_v2.aspx?routingGuid=34537f7c-cc43-45ef-bc9a-9820641bf718 | Q39: http://grls.rosminzdrav.ru/Grls_View_v2.aspx?routingGuid=dbe0bb34-ff56-47e4-9873-0133b28f09c9&t=
A40: 39 | B40: Influvac | C40: https://grls.rosminzdrav.ru/Grls_View_v2.aspx?routingGuid=f0e5ea62-1cea-4427-923d-201a87349492 | D40: Инфлювак | E40: Инфлювак® (вакцина гриппозная субъединичная инактивированная) | G40: in use | K40: 44712 | L40: 46130 | M40: есть | N40: https://grls.rosminzdrav.ru/Grls_View_v2.aspx?routingGuid=f0e5ea62-1cea-4427-923d-201a87349492 | O40: есть | P40: https://grls.rosminzdrav.ru/Grls_View_v2.aspx?routingGuid=d1eda2da-96d0-46b8-883a-7358a06372b2 | Q40: http://grls.rosminzdrav.ru/Grls_View_v2.aspx?routingGuid=fec37fbb-555f-4f09-832e-e55c4adf9598&t= https://grls.rosminzdrav.ru/Grls_View_v2.aspx?routingGuid=bbe4964e-190b-475d-bc21-5df56876bcc3&t= https://grls.rosminzdrav.ru/Grls_View_v2.aspx?routingGuid=904ea0a9-2557-42e6-b1fe-cf2e3d5a2a5f
...

Sheet ingredients_text
A1: vaccine_id | B1: code_name | C1: ingredients_text_w/o_html | D1: ingredients_text_html | E1: ingredients_date | F1: ingredients_view_number | G1: ingredients_version | H1: ingredients_version_link | I1: creation_date | J1: update_date | K1: comment
A2: 1 | B2: =VLOOKUP(A2,[1]vaccines!A:B,2) -> BCG_Microgen | C2: 1 доза (0,1 мл) содержит: Действующее вещество: микробные клетки Mycobacterium bovis BCG-I — 0,05 мг*. Полный перечень вспомогательных веществ приведен в разделе 6.1. Препарат не содержит консервантов и антибиотиков. Выпускается в комплекте с растворителем — натрия хлорид растворитель для приготовления лекарственных форм для инъекций 0,9 %. * расчетное содержание в 1 дозе. 6.1. Перечень вспомогательных веществ Лиофилизат: • Натрия глутамата моногидрат. | D2: <p>1&nbsp;доза (0,1&nbsp;мл) содержит:<br><br> Действующее вещество: микробные клетки <i>Mycobacterium bovis BCG-I</i> — 0,05&nbsp;мг*.<br> Полный перечень вспомогательных веществ приведен в разделе&nbsp;6.1.<br> Препарат не содержит консервантов и антибиотиков.<br> Выпускается в комплекте с растворителем — натрия хлорид растворитель для приготовления лекарственных форм для инъекций 0,9&nbsp;%.<br><br> *&nbsp;расчетное содержание в 1&nbsp;дозе.<br><br> <b>6.1.&nbsp;Перечень вспомогательных веществ</b><br><br> <i>Лиофилизат:</i> <ul><li>Натрия глутамата моногидрат.</li></ul></p> | E2: 45461 | H2: https://lk.regmed.ru/Register/GetPDFfromDA?ID=1597322951 | I2: 45105 | J2: 45517 | K2: добавлено Елена Савинова
A3: 2 | B3: =VLOOKUP(A3,[1]vaccines!A:B,2) -> BCG_M_Microgen | C3: 1 доза (0,1 мл) содержит: Действующее вещество: микробные клетки Mycobacterium bovis BCG-I — 0,025 мг*. Полный перечень вспомогательных веществ приведен в разделе 6.1. Препарат не содержит консервантов и антибиотиков. Выпускается в комплекте с растворителем — натрия хлорид растворитель для приготовления лекарственных форм для инъекций 0,9 %. * расчетное содержание в 1 дозе. 6.1. Перечень вспомогательных веществ • Натрия глутамата моногидрат. | D3: <p>1&nbsp;доза (0,1&nbsp;мл) содержит:<br><br> Действующее вещество: микробные клетки <i>Mycobacterium bovis BCG-I</i> — 0,025&nbsp;мг*.<br> Полный перечень вспомогательных веществ приведен в разделе&nbsp;6.1.<br> Препарат не содержит консервантов и антибиотиков.<br> Выпускается в комплекте с растворителем — натрия хлорид растворитель для приготовления лекарственных форм для инъекций 0,9&nbsp;%.<br><br> *&nbsp;расчетное содержание в 1&nbsp;дозе.<br><br> <b>6.1.&nbsp;Перечень вспомогательных веществ</b> <ul><li>Натрия глутамата моногидрат.</li></ul></p> | E3: 45461 | H3: https://lk.regmed.ru/Register/GetPDFfromDA?ID=1597318981 | I3: 45107 | J3: 45517 | K3: проверено Елена Савинова
A4: 3 | B4: =VLOOKUP(A4,[1]vaccines!A:B,2) -> BCG_Gamaleya | C4: В одной дозе содержится: • 0,05 мг Микобактерий вакцинного штамма Mycobacterium bovis, субштамм BCG-1 (Russia). Перечень вспомогательных веществ: • Стабилизатор — натрия глутамат моногидрат — не более 0,3 мг; • Раствор натрия хлорида 0,9 % для инъекций — до 0,1 мл. | D4: <p>В одной дозе содержится: <ul><li>0,05&nbsp;мг Микобактерий вакцинного штамма <i>Mycobacterium bovis</i>, субштамм BCG-1 (Russia).</li></ul> Перечень вспомогательных веществ: <ul><li>Стабилизатор — натрия глутамат моногидрат — не более 0,3&nbsp;мг;</li> <li>Раствор натрия хлорида 0,9&nbsp;% для инъекций — до 0,1&nbsp;мл.</li></ul></p> | E4: 45769 | F4: 1 | G4: 0 | H4: https://grls.rosminzdrav.ru/InstrImg/2025/05/19/1517351/3bec22d2-65bc-4a94-9482-413901e57760.pdf | I4: 45108 | J4: 45801
A5: 4 | B5: =VLOOKUP(A5,[1]vaccines!A:B,2) -> BCG_M_Gamaleya | C5: В одной дозе содержится: • 0,025 мг Микобактерий вакцинного штамма Mycobacterium bovis, субштамм BCG-1 (Russia). Перечень вспомогательных веществ: • Стабилизатор — натрия глутамат моногидрат — не более 0,15 мг; • Раствор натрия хлорида 0,9 % для инъекций — до 0,1 мл. | D5: <p>В одной дозе содержится: <ul><li>0,025&nbsp;мг Микобактерий вакцинного штамма Mycobacterium bovis, субштамм BCG-1 (Russia).</li></ul> Перечень вспомогательных веществ: <ul><li>Стабилизатор — натрия глутамат моногидрат — не более 0,15&nbsp;мг;</li> <li>Раствор натрия хлорида 0,9&nbsp;% для инъекций — до 0,1&nbsp;мл.</li></ul></p> | E5: 45771 | F5: 1 | G5: 0 | H5: https://grls.rosminzdrav.ru/InstrImg/2025/06/02/1517794/d7367d9e-e745-46a7-b297-5a093bf3738a.pdf | I5: =I4 -> 45108 | J5: 45818
A6: 5 | B6: =VLOOKUP(A6,[1]vaccines!A:B,2) -> Infanrix | C6: 1 доза (0,5 мл) вакцины содержит: Действующие вещества: • анатоксин дифтерийный¹·³ — не менее 30 МЕ; • анатоксин столбнячный²·³ — не менее 40 МЕ; • анатоксин коклюшный (АК)³ — 25 мкг; • гемагглютинин филаментозный (ФГА)³ — 25 мкг; • пертактин (ПРН)³ (белок наружной мембраны 69 кДа) — 8 мкг. ¹ Содержание дифтерийного анатоксина 25 Lf (флоккулирующих единиц). ² Содержание столбнячного анатоксина 10 Lf (флоккулирующих единиц). ³ Адсорбированный на алюминия гидроксиде (0,5 мг в пересчете на алюминий). Перечень вспомогательных веществ: • Натрия хлорид. • Вода для инъекций. | D6: <p>1&nbsp;доза (0,5&nbsp;мл) вакцины содержит:<br><br> <i>Действующие вещества:</i> <ul><li>анатоксин дифтерийный¹<sup>,</sup>³ — не менее 30&nbsp;МЕ;</li> <li>анатоксин столбнячный²<sup>,</sup>³ — не менее 40&nbsp;МЕ;</li> <li>анатоксин коклюшный (АК)³ — 25&nbsp;мкг;</li> <li>гемагглютинин филаментозный (ФГА)³ — 25&nbsp;мкг;</li> <li>пертактин (ПРН)³ (белок наружной мембраны 69&nbsp;кДа) — 8&nbsp;мкг.</li></ul> ¹&nbsp;Содержание дифтерийного анатоксина 25&nbsp;Lf (флоккулирующих единиц).<br> ²&nbsp;Содержание столбнячного анатоксина 10&nbsp;Lf (флоккулирующих единиц).<br> ³&nbsp;Адсорбированный на алюминия гидроксиде (0,5&nbsp;мг в пересчете на алюминий).<br><br> <i>Перечень вспомогательных веществ:</i> <ul><li>Натрия хлорид.</li> <li>Вода для инъекций.</li></ul></p> | E6: 44211 | H6: https://lk.regmed.ru/Register/GetPDFfromDA?ID=1484709711 | I6: 45105 | J6: 45481 | K6: добавлено Елена Савинова
A7: 6 | B7: =VLOOKUP(A7,[1]vaccines!A:B,2) -> AKDS_Microgen | C7: В 1 дозе (0,5 мл) содержится: Препарат с консервантом. Действующие вещества: • анатоксин дифтерийный¹ — 15 флокулирующих единиц (Lf); • анатоксин столбнячный¹ — 5 единиц связывания (EC); • коклюшная суспензия инактивированная — 10 млрд коклюшных микробных клеток. ¹ - Адсорбированный на алюминия гидроксиде (в пересчете на Al³⁺) — не более 0,55 мг; Препарат без консерванта. Действующие вещества: • анатоксин дифтерийный¹ — 15 флокулирующих единиц (Lf); • анатоксин столбнячный¹ — 5 единиц связывания (EC); • коклюшная суспензия инактивированная без тиомерсала — 10 млрд коклюшных микробных клеток. ¹ - Адсорбированный на алюминия гидроксиде (в пересчете на Al³⁺) — не более 0,55 мг; Перечень вспомогательных веществ: Препарат с консервантом. • Алюминия гидроксид; • Формальдегид; • Консервант — тиомерсал. Препарат без консерванта. • Алюминия гидроксид; • Формальдегид. | D7: <p>В 1&nbsp;дозе (0,5&nbsp;мл) содержится:<br><br> <i>Препарат с консервантом.</i><br><br> Действующие вещества: <ul><li>анатоксин дифтерийный¹ — 15&nbsp;флокулирующих единиц (Lf);</li> <li>анатоксин столбнячный¹ — 5&nbsp;единиц связывания (EC);</li> <li>коклюшная суспензия инактивированная — 10&nbsp;млрд коклюшных микробных клеток.</li></ul> ¹&nbsp;- Адсорбированный на алюминия гидроксиде (в пересчете на Al³⁺) — не более 0,55&nbsp;мг;<br><br> <i>Препарат без консерванта.</i><br><br> Действующие вещества: <ul><li>анатоксин дифтерийный¹ — 15&nbsp;флокулирующих единиц (Lf);</li> <li>анатоксин столбнячный¹ — 5&nbsp;единиц связывания (EC);</li> <li>коклюшная суспензия инактивированная без тиомерсала — 10&nbsp;млрд коклюшных микробных клеток.</li></ul> ¹&nbsp;- Адсорбированный на алюминия гидроксиде (в пересчете на Al³⁺) — не более 0,55&nbsp;мг;<br><br> Перечень вспомогательных веществ:<br><br> <i>Препарат с консервантом.</i> <ul><li>Алюминия гидроксид;</li> <li>Формальдегид;</li> <li>Консервант — тиомерсал.</li></ul> <i>Препарат без консерванта.</i> <ul><li>Алюминия гидроксид;</li> <li>Формальдегид.</li></ul></p> | E7: 45415 | H7: https://lk.regmed.ru/Register/GetPDFfromDA?ID=1587927891 | I7: 45115 | J7: 45461
A8: 7 | B8: =VLOOKUP(A8,[1]vaccines!A:B,2) -> AKDS_Biomed | C8: АКДС-вакцина состоит из взвеси убитых коклюшных микробов и очищенных дифтерийного и столбнячного анатоксинов, сорбированных на алюминия гидроксиде. В одной дозе препарата (0,5 мл) содержится 10 международных единиц (МЕ) инактивированных коклюшных микробов, 15 флокулирующих единиц (Lf) дифтерийного, 5 единиц связывания (EC) столбнячного анатоксинов, от 0,25 до 0,55 мг алюминия гидроксида в пересчете на алюминий (сорбент), от 42,5 до 57,5 мкг тиомерсала (консервант). | D8: <p>В одной дозе препарата (0,5&nbsp;мл) содержится 10&nbsp;международных единиц (МЕ) инактивированных коклюшных микробов, 15&nbsp;флокулирующих единиц (Lf) дифтерийного, 5&nbsp;единиц связывания (EC) столбнячного анатоксинов, от 0,25 до 0,55&nbsp;мг алюминия гидроксида в пересчете на алюминий (сорбент), от 42,5 до 57,5&nbsp;мкг тиомерсала (консервант).</p> | E8: 41388 | F8: 1 | G8: 0 | H8: https://grls.rosminzdrav.ru/InstrImg/2017/4/26/1416322/%D0%A0_N002666_01[2013]_0.pdf | I8: 45115
A9: 8 | B9: =VLOOKUP(A9,[1]vaccines!A:B,2) -> Bubo_kok | C9: Препарат содержит в одной дозе (0,5 мл): 15 флокулирующих единиц (Lf) дифтерийного, 5 единиц связывания (EC) столбнячного анатоксинов, 10 млрд коклюшных бактерий, 5 мкг HBsAg, 0,4 мг алюминия гидроксида (Al³⁺), 50 мкг мертиолята (консервант). | D9: <p>Препарат содержит в одной дозе (0,5&nbsp;мл): 15&nbsp;флокулирующих единиц (Lf) дифтерийного, 5&nbsp;единиц связывания (EC) столбнячного анатоксинов, 10&nbsp;млрд коклюшных бактерий, 5&nbsp;мкг HBsAg, 0,4&nbsp;мг алюминия гидроксида (Al³⁺), 50&nbsp;мкг мертиолята (консервант).</p> | E9: 40395 | F9: 1 | G9: 0 | H9: https://grls.rosminzdrav.ru/InstrImg/2020/05/28/10700/9d141b34-47e7-48c8-9480-616cbbc792fc.pdf | I9: 45115
A10: 9 | B10: =VLOOKUP(A10,[1]vaccines!A:B,2) -> Pentaxim | C10: Действующими веществами являются: После восстановления 1 доза (0,5 мл) содержит: Изначально в виде суспензии: • Анатоксин дифтерийный¹ — 30 Lf (≥ 30 МЕ²)³; • Анатоксин столбнячный¹ — 10 LF (≥ 40 МЕ⁴)³; • Анатоксин коклюшный¹ — 25 мкг; • Гемагглютинин филаментозный¹ — 25 мкг; • Вирус полиомиелита 1-го типа инактивированный (Mahoney)⁵ — 40 единиц D антигена⁶; • Вирус полиомиелита 2-го типа инактивированный (MEF-1)⁵ — 8 единиц D антигена⁶; • Вирус полиомиелита 3-го типа инактивированный (Saukett)⁵ — 32 единицы D антигена⁶. Изначально в виде лиофилизата для приготовления суспензии: • Полисахарид Haemophilus influenzae тип b (полирибозилрибитол фосфат) — 10 мкг, конъюгированный со столбнячным анатоксином — 18-30 мкг. ¹ — адсорбирован на алюминия гидроксида гидрате (0,3 мг в пересчете на алюминий); ² — в качестве среднего значения, нижний предел доверительного интервала (р = 0,95) не менее 20 МЕ/доза; ³ — или эквивалентная активность, определенная при оценке иммуногенности; ⁴ — нижний предел доверительного интервала (р = 0,95); ⁵ — культивированный на клетках VERO; ⁶ — или эквивалентное содержание антигена, определенное подходящим иммунохимическим методом. Антибиотики (стрептомицин, неомицин и полимиксин В) и глутаральдегид используются при производстве вакцины, но не присутствуют в определяемых количествах в конечном продукте. Вспомогательные вещества, наличие которых надо учитывать в составе вакцины: фенилаланин Перечень вспомогательных веществ: Суспензия для внутримышечного введения: • Алюминия гидроксида гидрат; • Раствор формальдегида; • Феноксиэтанол; • Этанол безводный; • Среда Хенкса 199 (10×) без фенолового красного (представляет собой сложную смесь аминокислот (включая фенилаланин), минералов, витаминов и других компонентов (таких как глюкоза), разведенную в воде для инъекций); • Натрия гидроксид или ледяная уксусная кислота используются для корректировки рН; • Вода для инъекций. Лиофилизат для приготовления суспензии для внутримышечного введения: • Трометамол; • Сахароза; • Концентрированная хлористоводородная кислота для корректировки рН (до 7,2 ± 0,1). | D10: <p>Действующими веществами являются:<br> После восстановления 1&nbsp;доза (0,5&nbsp;мл) содержит:<br><br> <i>Изначально в виде суспензии:</i> <ul><li>Анатоксин дифтерийный¹ — 30&nbsp;Lf (≥&nbsp;30&nbsp;МЕ²)³;</li> <li>Анатоксин столбнячный¹ — 10&nbsp;LF (≥&nbsp;40&nbsp;МЕ⁴)³;</li> <li>Анатоксин коклюшный¹ — 25&nbsp;мкг;</li> <li>Гемагглютинин филаментозный¹ — 25&nbsp;мкг;</li> <li>Вирус полиомиелита 1-го&nbsp;типа инактивированный (Mahoney)⁵ — 40&nbsp;единиц D&nbsp;антигена⁶;</li> <li>Вирус полиомиелита 2-го&nbsp;типа инактивированный (MEF-1)⁵ — 8&nbsp;единиц D&nbsp;антигена⁶;</li> <li>Вирус полиомиелита 3-го&nbsp;типа инактивированный (Saukett)⁵ — 32&nbsp;единицы D&nbsp;антигена⁶.</li></ul> <i>Изначально в виде лиофилизата для приготовления суспензии:</i> <ul><li>Полисахарид Haemophilus influenzae тип b (полирибозилрибитол фосфат) — 10&nbsp;мкг,<br> конъюгированный со столбнячным анатоксином — 18-30&nbsp;мкг.</li></ul> ¹ — адсорбирован на алюминия гидроксида гидрате (0,3&nbsp;мг в пересчете на алюминий);<br> ² — в качестве среднего значения, нижний предел доверительного интервала (р&nbsp;=&nbsp;0,95) не менее 20&nbsp;МЕ/доза;<br> ³ — или эквивалентная активность, определенная при оценке иммуногенности;<br> ⁴ — нижний предел доверительного интервала (р&nbsp;=&nbsp;0,95);<br> ⁵ — культивированный на клетках VERO;<br> ⁶ — или эквивалентное содержание антигена, определенное подходящим иммунохимическим методом.<br><br> Антибиотики (стрептомицин, неомицин и полимиксин В) и глутаральдегид используются при производстве вакцины, но не присутствуют в определяемых количествах в конечном продукте.<br> Вспомогательные вещества, наличие которых надо учитывать в составе вакцины: фенилаланин<br><br> Перечень вспомогательных веществ:<br> <i>Суспензия для внутримышечного введения:</i> <ul><li>Алюминия гидроксида гидрат;</li> <li>Раствор формальдегида;</li> <li>Феноксиэтанол;</li> <li>Этанол безводный;</li> <li>Среда Хенкса&nbsp;199 (10×) без фенолового красного (представляет собой сложную смесь аминокислот (включая фенилаланин), минералов, витаминов и других компонентов (таких как глюкоза), разведенную в воде для инъекций);</li> <li>Натрия гидроксид или ледяная уксусная кислота используются для корректировки рН;</li> <li>Вода для инъекций.</li></ul> <i>Лиофилизат для приготовления суспензии для внутримышечного введения:</i> <ul><li>Трометамол;</li> <li>Сахароза;</li> <li>Концентрированная хлористоводородная кислота для корректировки рН (до 7,2&nbsp;±&nbsp;0,1).</li></ul></p> | E10: 45980 | F10: 1 | G10: 0 | H10: https://grls.rosminzdrav.ru/InstrImg/2026/05/27/1530421/6bdc8421-6c08-4bf7-be7f-0ae5d96a478d.pdf | I10: =I9 -> 45115 | J10: 46204 | K10: zaytseva@vaccina.info не нашла символ запятой в верхнем индексе, который бы нормально копировался сюда, поэтому здесь и далее в столбце "ingredients_text_w/o_html" вместо него символ "·". В столбце "ingredients_text_html" запятая в верхнем индексе поставлена с помощью тэга <sup>.
A11: 10 | B11: =VLOOKUP(A11,[1]vaccines!A:B,2) -> Infanrix_Hexa | C11: 1 доза (0,5 мл) вакцины содержит: Вакцина для профилактики дифтерии, столбняка, коклюша (бесклеточная), полиомиелита (инактивированная), гепатита В комбинированная, адсорбированная Действующие вещества: • Анатоксин дифтерийный¹·³ — Не менее 30 МЕ; • Анатоксин столбнячный²·³ — Не менее 40 МЕ; • Анатоксин коклюшный (АК)³ — 25 мкг; • Гемагглютинин филаментозный (ФГА)³ — 25 мкг; • Пертактин (белок наружной мембраны 69 кДа)³ — 8 мкг; • Антиген поверхностный рекомбинантный вируса гепатита B (HBsAg)⁴ — 10 мкг; • Вирус полиомиелита тип 1 инактивированный — 40 ЕД D-антигена; • Вирус полиомиелита тип 2 инактивированный — 8 ЕД D-антигена; • Вирус полиомиелита тип 3 инактивированный — 32 ЕД D-антигена. Вакцина для профилактики инфекции, вызываемой Haemophilus influenzae тип b конъюгированная, адсорбированная Действующее вещество: • Капсульный полисахарид Haemophilus influenzae тип b⁴ — 10 мкг; конъюгированный со столбнячным анатоксином — ≈25 мкг. ¹ Содержание дифтерийного анатоксина 25 Lf (флоккулирующих единиц). ² Содержание столбнячного анатоксина 10 Lf (флоккулирующих единиц). ³ Адсорбированный на алюминия гидроксиде (0,5 мг в пересчете на алюминий). ⁴ Адсорбированный на алюминия фосфате (0,32 мг в пересчете на алюминий). Перечень вспомогательных веществ: Вакцина для профилактики дифтерии, столбняка, коклюша (бесклеточная), полиомиелита (инактивированная), гепатита В комбинированная, адсорбированная: • Натрия хлорид. • Среда 199 (М 199)¹ (включая аминокислоты). • Вода для инъекций. ¹ Состав среды 199 (М 199): кальция хлорида дигидрат, железа нитрата нонагидрат, калия хлорид, калия дигидрофосфат, магния сульфата гептагидрат, натрия хлорид, натрия гидрокарбонат, натрия гидрофосфат, L-аланин, L-аргинина гидрохлорид, L-аспарагиновая кислота, L-цистеина гидрохлорид, L-цистин, L-глутаминовая кислота, L-глутамин, глицин, L-гистидина гидрохлорида моногидрат, L-гидроксипролин, L-изолейцин, L-лейцин, L-лизина гидрохлорид, L-метионин, L-фенилаланин, L-пролин, L-серин, L-треонин, L-триптофан, L-тирозин, L-валин, аскорбиновая кислота, альфа-токоферол, биотин, кальциферол, кальция пантотенат, холина хлорид, фолиевая кислота, инозитол, менадион, никотиновая кислота, никотинамид, пара-аминобензойная кислота, пиридоксаль гидрохлорид, пиридоксина гидрохлорид, рибофлавин, тиамина гидрохлорид, ретинола ацетат, аденин, аденозина фосфат, аденозина трифосфат натрия, холестерол, дезоксирибоза, глюкоза, глутатион, гуанина гидрохлорид, гипоксантин, рибоза, натрия ацетат, тимин, твин-80, урацил, ксантин. Вакцина для профилактики инфекции, вызываемой Haemophilus influenzae тип b, конъюгированная, адсорбированная: • Лактоза. Данный препарат содержит менее 1 ммоль (23 мг) натрия на 1 дозу, то есть по сути не содержит натрия. | D11: <p>1&nbsp;доза (0,5&nbsp;мл) вакцины содержит:<br><br> Вакцина для профилактики дифтерии, столбняка, коклюша (бесклеточная), полиомиелита (инактивированная), гепатита В комбинированная, адсорбированная <ul><i>Действующие вещества:</i> <li>Анатоксин дифтерийный¹<sup>,</sup>³ — Не менее 30&nbsp;МЕ;</li> <li>Анатоксин столбнячный²<sup>,</sup>³ — Не менее 40&nbsp;МЕ;</li> <li>Анатоксин коклюшный (АК)³ — 25&nbsp;мкг;</li> <li>Гемагглютинин филаментозный (ФГА)³ — 25&nbsp;мкг;</li> <li>Пертактин (белок наружной мембраны 69&nbsp;кДа)³ — 8&nbsp;мкг;</li> <li>Антиген поверхностный рекомбинантный вируса гепатита B (HBsAg)⁴ — 10&nbsp;мкг;</li> <li>Вирус полиомиелита тип&nbsp;1 инактивированный — 40&nbsp;ЕД D-антигена;</li> <li>Вирус полиомиелита тип&nbsp;2 инактивированный — 8&nbsp;ЕД D-антигена;</li> <li>Вирус полиомиелита тип&nbsp;3 инактивированный — 32&nbsp;ЕД D-антигена.</li></ul> Вакцина для профилактики инфекции, вызываемой <i>Haemophilus influenzae</i> тип <i>b</i> конъюгированная, адсорбированная <ul><i>Действующее вещество:</i> <li>Капсульный полисахарид Haemophilus influenzae тип b⁴ — 10&nbsp;мкг;<br> конъюгированный со столбнячным анатоксином — ≈25&nbsp;мкг.</li></ul> ¹ Содержание дифтерийного анатоксина 25&nbsp;Lf (флоккулирующих единиц).<br> ² Содержание столбнячного анатоксина 10&nbsp;Lf (флоккулирующих единиц).<br> ³ Адсорбированный на алюминия гидроксиде (0,5&nbsp;мг в пересчете на алюминий).<br> ⁴ Адсорбированный на алюминия фосфате (0,32&nbsp;мг в пересчете на алюминий).</p> <p><i>Перечень вспомогательных веществ:</i><br><br> Вакцина для профилактики дифтерии, столбняка, коклюша (бесклеточная), полиомиелита (инактивированная), гепатита В комбинированная, адсорбированная: <ul><li>Натрия хлорид.</li> <li>Среда&nbsp;199 (М&nbsp;199)¹ (включая аминокислоты).</li> <li>Вода для инъекций.</li></ul> ¹ Состав среды&nbsp;199 (М&nbsp;199):<br> кальция хлорида дигидрат, железа нитрата нонагидрат, калия хлорид, калия дигидрофосфат, магния сульфата гептагидрат, натрия хлорид, натрия гидрокарбонат, натрия гидрофосфат, L-аланин, L-аргинина гидрохлорид, L-аспарагиновая кислота, L-цистеина гидрохлорид, L-цистин, L-глутаминовая кислота, L-глутамин, глицин, L-гистидина гидрохлорида моногидрат, L-гидроксипролин, L-изолейцин, L-лейцин, L-лизина гидрохлорид, L-метионин, L-фенилаланин, L-пролин, L-серин, L-треонин, L-триптофан, L-тирозин, L-валин, аскорбиновая кислота, альфа-токоферол, биотин, кальциферол, кальция пантотенат, холина хлорид, фолиевая кислота, инозитол, менадион, никотиновая кислота, никотинамид, пара-аминобензойная кислота, пиридоксаль гидрохлорид, пиридоксина гидрохлорид, рибофлавин, тиамина гидрохлорид, ретинола ацетат, аденин, аденозина фосфат, аденозина трифосфат натрия, холестерол, дезоксирибоза, глюкоза, глутатион, гуанина гидрохлорид, гипоксантин, рибоза, натрия ацетат, тимин, твин-80, урацил, ксантин.<br><br> Вакцина для профилактики инфекции, вызываемой <i>Haemophilus influenzae</i> тип <i>b</i>, конъюгированная, адсорбированная: <ul><li>Лактоза.</li></ul> Данный препарат содержит менее 1&nbsp;ммоль (23&nbsp;мг) натрия на 1&nbsp;дозу, то есть по сути не содержит натрия.</p> | E11: 45953 | F11: 1 | G11: 0 | H11: https://grls.rosminzdrav.ru/InstrImg/2025/12/04/1523945/374687b9-516b-4eb9-9e34-640e88c2e1e2.pdf | I11: =I10 -> 45115 | J11: 46000
A12: 11 | B12: =VLOOKUP(A12,[1]vaccines!A:B,2) -> Bubo_M | C12: 1 доза (0,5 мл) содержит действующие вещества: • Антиген вируса гепатита В поверхностный рекомбинантный (HBsAg) (серотип ay и/или ad)¹ — 10 мкг; • дифтерийный анатоксин очищенный концентрированный жидкий (ОКДА)¹ — 5 Lf (флокулирующих единиц); • столбнячный анатоксин очищенный концентрированный жидкий (ОКСА)¹ — 5 ЕС (антитоксинсвязывающих единиц). ¹ — адсорбированный на алюминия гидроксиде (Al³⁺) — 0,45 мг. Перечень вспомогательных веществ: • Тиомерсал (консервант). | D12: <p>1&nbsp;доза (0,5&nbsp;мл) содержит действующие вещества: <ul><li>Антиген вируса гепатита&nbsp;В поверхностный рекомбинантный (HBsAg) (серотип ay и/или ad)¹ — 10&nbsp;мкг;</li> <li>дифтерийный анатоксин очищенный концентрированный жидкий (ОКДА)¹ — 5&nbsp;Lf (флокулирующих единиц);</li> <li>столбнячный анатоксин очищенный концентрированный жидкий (ОКСА)¹ — 5&nbsp;ЕС (антитоксинсвязывающих единиц).</li></ul> ¹&nbsp;—&nbsp;адсорбированный на алюминия гидроксиде (Al³⁺) — 0,45&nbsp;мг.<br><br> <i>Перечень вспомогательных веществ:</i> <ul><li>Тиомерсал (консервант).</li></ul></p> | E12: 46136 | F12: 1 | G12: 0 | H12: https://grls.rosminzdrav.ru/InstrImg/2026/06/02/1530636/e301156c-c7d5-45d7-bf58-5346c270c493.pdf | I12: 45116 | J12: 46188
