Workbook

Sheet vaccines
A1: =IFERROR(__xludf.DUMMYFUNCTION("importrange(""https://docs.google.com/spreadsheets/d/1sGRvhluuPcwgfCszZJeTSVDmdr-8joz4WvlOQo2gfes/edit?usp=drivesdk"",""vaccines!A:M"")"),"id") -> id | B1: =IFERROR(__xludf.DUMMYFUNCTION("""COMPUTED_VALUE"""),"code_name") -> code_name | C1: =IFERROR(__xludf.DUMMYFUNCTION("""COMPUTED_VALUE"""),"product_characteristics_link_primary_field_for_version_1") -> product_characteristics_link_primary_field_for_version_1 | D1: =IFERROR(__xludf.DUMMYFUNCTION("""COMPUTED_VALUE"""),"short_name") -> short_name | E1: =IFERROR(__xludf.DUMMYFUNCTION("""COMPUTED_VALUE"""),"long_name") -> long_name | F1: =IFERROR(__xludf.DUMMYFUNCTION("""COMPUTED_VALUE"""),"manufacturer") -> manufacturer | G1: =IFERROR(__xludf.DUMMYFUNCTION("""COMPUTED_VALUE"""),"in_use_in_Russia") -> in_use_in_Russia | H1: =IFERROR(__xludf.DUMMYFUNCTION("""COMPUTED_VALUE"""),"comment_to_show") -> comment_to_show | I1: =IFERROR(__xludf.DUMMYFUNCTION("""COMPUTED_VALUE"""),"comment_to_show_wo_html") -> comment_to_show_wo_html | J1: =IFERROR(__xludf.DUMMYFUNCTION("""COMPUTED_VALUE"""),"dosage") -> dosage | K1: =IFERROR(__xludf.DUMMYFUNCTION("""COMPUTED_VALUE"""),"creation_date") -> creation_date | L1: =IFERROR(__xludf.DUMMYFUNCTION("""COMPUTED_VALUE"""),"update_date") -> update_date | M1: =IFERROR(__xludf.DUMMYFUNCTION("""COMPUTED_VALUE"""),"OKhLP_specialists_link") -> OKhLP_specialists_link
A2: =IFERROR(__xludf.DUMMYFUNCTION("""COMPUTED_VALUE"""),1.0) -> 1 | B2: =IFERROR(__xludf.DUMMYFUNCTION("""COMPUTED_VALUE"""),"BCG_Microgen") -> BCG_Microgen | C2: =IFERROR(__xludf.DUMMYFUNCTION("""COMPUTED_VALUE"""),"https://grls.rosminzdrav.ru/Grls_View_v2.aspx?routingGuid=9f91626d-1063-4ea5-9346-800cc6ef9b44") -> https://grls.rosminzdrav.ru/Grls_View_v2.aspx?routingGuid=9f91626d-1063-4ea5-9346-800cc6ef9b44 | D2: =IFERROR(__xludf.DUMMYFUNCTION("""COMPUTED_VALUE"""),"БЦЖ (Микроген)") -> БЦЖ (Микроген) | E2: =IFERROR(__xludf.DUMMYFUNCTION("""COMPUTED_VALUE"""),"Вакцина туберкулезная (БЦЖ)") -> Вакцина туберкулезная (БЦЖ) | F2: =IFERROR(__xludf.DUMMYFUNCTION("""COMPUTED_VALUE"""),"Микроген") -> Микроген | G2: =IFERROR(__xludf.DUMMYFUNCTION("""COMPUTED_VALUE"""),"in use") -> in use | H2: =IFERROR(__xludf.DUMMYFUNCTION("""COMPUTED_VALUE"""),"<p>Используется в двух случаях: <ol><li>на тех территориях, где показатель заболеваемости туберкулеза превышает 80&nbsp;случаев на 100&nbsp;000&nbsp;населения;</li> <li>если в окружении новорожденного есть больной туберкулезом.</li></ol></p>") -> <p>Используется в двух случаях: <ol><li>на тех территориях, где показатель заболеваемости туберкулеза превышает 80&nbsp;случаев на 100&nbsp;000&nbsp;населения;</li> <li>если в окружении новорожденного есть больной туберкулезом.</li></ol></p> | I2: =IFERROR(__xludf.DUMMYFUNCTION("""COMPUTED_VALUE"""),"Используется в двух случаях: 1. на тех территориях, где показатель заболеваемости туберкулеза превышает 80 случаев на 100 000 населения; 2. если в окружении новорожденного есть больной туберкулезом.") -> Используется в двух случаях: 1. на тех территориях, где показатель заболеваемости туберкулеза превышает 80 случаев на 100 000 населения; 2. если в окружении новорожденного есть больной туберкулезом. | J2: =IFERROR(__xludf.DUMMYFUNCTION("""COMPUTED_VALUE"""),0.05) -> 0.05 | K2: =IFERROR(__xludf.DUMMYFUNCTION("""COMPUTED_VALUE"""),44712.0) -> 44712 | L2: =IFERROR(__xludf.DUMMYFUNCTION("""COMPUTED_VALUE"""),45689.0) -> 45689 | M2: =IFERROR(__xludf.DUMMYFUNCTION("""COMPUTED_VALUE"""),"есть") -> есть
A3: =IFERROR(__xludf.DUMMYFUNCTION("""COMPUTED_VALUE"""),2.0) -> 2 | B3: =IFERROR(__xludf.DUMMYFUNCTION("""COMPUTED_VALUE"""),"BCG_M_Microgen") -> BCG_M_Microgen | C3: =IFERROR(__xludf.DUMMYFUNCTION("""COMPUTED_VALUE"""),"https://grls.rosminzdrav.ru/Grls_View_v2.aspx?routingGuid=115ba81b-7cb9-4737-9e63-163458ef9d0b") -> https://grls.rosminzdrav.ru/Grls_View_v2.aspx?routingGuid=115ba81b-7cb9-4737-9e63-163458ef9d0b | D3: =IFERROR(__xludf.DUMMYFUNCTION("""COMPUTED_VALUE"""),"БЦЖ-М (Микроген)") -> БЦЖ-М (Микроген) | E3: =IFERROR(__xludf.DUMMYFUNCTION("""COMPUTED_VALUE"""),"Вакцина туберкулезная для щадящей первичной иммунизации (БЦЖ-М)") -> Вакцина туберкулезная для щадящей первичной иммунизации (БЦЖ-М) | F3: =IFERROR(__xludf.DUMMYFUNCTION("""COMPUTED_VALUE"""),"Микроген") -> Микроген | G3: =IFERROR(__xludf.DUMMYFUNCTION("""COMPUTED_VALUE"""),"in use") -> in use | H3: =IFERROR(__xludf.DUMMYFUNCTION("""COMPUTED_VALUE"""),"<p>Используется по умолчанию для вакцинации детей против туберкулеза. Однако на территориях с повышенной заболеваемостью туберкулезом, а также если в окружении новорожденного есть больной туберкулезом, используется другая вакцина — ""БЦЖ"".</p>") -> <p>Используется по умолчанию для вакцинации детей против туберкулеза. Однако на территориях с повышенной заболеваемостью туберкулезом, а также если в окружении новорожденного есть больной туберкулезом, используется другая вакцина — "БЦЖ".</p> | I3: =IFERROR(__xludf.DUMMYFUNCTION("""COMPUTED_VALUE"""),"Используется по умолчанию для вакцинации детей против туберкулеза. Однако на территориях с повышенной заболеваемостью туберкулезом, а также если в окружении новорожденного есть больной туберкулезом, используется другая вакцина — ""БЦЖ"".") -> Используется по умолчанию для вакцинации детей против туберкулеза. Однако на территориях с повышенной заболеваемостью туберкулезом, а также если в окружении новорожденного есть больной туберкулезом, используется другая вакцина — "БЦЖ". | J3: =IFERROR(__xludf.DUMMYFUNCTION("""COMPUTED_VALUE"""),0.025) -> 0.025 | K3: =IFERROR(__xludf.DUMMYFUNCTION("""COMPUTED_VALUE"""),44712.0) -> 44712 | L3: =IFERROR(__xludf.DUMMYFUNCTION("""COMPUTED_VALUE"""),45689.0) -> 45689 | M3: =IFERROR(__xludf.DUMMYFUNCTION("""COMPUTED_VALUE"""),"есть") -> есть
A4: =IFERROR(__xludf.DUMMYFUNCTION("""COMPUTED_VALUE"""),3.0) -> 3 | B4: =IFERROR(__xludf.DUMMYFUNCTION("""COMPUTED_VALUE"""),"BCG_Gamaleya") -> BCG_Gamaleya | C4: =IFERROR(__xludf.DUMMYFUNCTION("""COMPUTED_VALUE"""),"https://grls.rosminzdrav.ru/Grls_View_v2.aspx?routingGuid=4215760f-875d-476b-a9b6-af2e398c3025") -> https://grls.rosminzdrav.ru/Grls_View_v2.aspx?routingGuid=4215760f-875d-476b-a9b6-af2e398c3025 | D4: =IFERROR(__xludf.DUMMYFUNCTION("""COMPUTED_VALUE"""),"БЦЖ (Гамалеи)") -> БЦЖ (Гамалеи) | E4: =IFERROR(__xludf.DUMMYFUNCTION("""COMPUTED_VALUE"""),"Вакцина туберкулезная (БЦЖ)") -> Вакцина туберкулезная (БЦЖ) | F4: =IFERROR(__xludf.DUMMYFUNCTION("""COMPUTED_VALUE"""),"НИЦЭМ им. Н.Ф. Гамалеи") -> НИЦЭМ им. Н.Ф. Гамалеи | G4: =IFERROR(__xludf.DUMMYFUNCTION("""COMPUTED_VALUE"""),"in use") -> in use | H4: =IFERROR(__xludf.DUMMYFUNCTION("""COMPUTED_VALUE"""),"<p>Используется в двух случаях: <ol><li>на тех территориях, где показатель заболеваемости туберкулеза превышает 80&nbsp;случаев на 100&nbsp;000&nbsp;населения;</li> <li>если в окружении новорожденного есть больной туберкулезом.</li></ol></p>") -> <p>Используется в двух случаях: <ol><li>на тех территориях, где показатель заболеваемости туберкулеза превышает 80&nbsp;случаев на 100&nbsp;000&nbsp;населения;</li> <li>если в окружении новорожденного есть больной туберкулезом.</li></ol></p> | I4: =IFERROR(__xludf.DUMMYFUNCTION("""COMPUTED_VALUE"""),"Используется в двух случаях: 1. на тех территориях, где показатель заболеваемости туберкулеза превышает 80 случаев на 100 000 населения; 2. если в окружении новорожденного есть больной туберкулезом.") -> Используется в двух случаях: 1. на тех территориях, где показатель заболеваемости туберкулеза превышает 80 случаев на 100 000 населения; 2. если в окружении новорожденного есть больной туберкулезом. | J4: =IFERROR(__xludf.DUMMYFUNCTION("""COMPUTED_VALUE"""),0.05) -> 0.05 | K4: =IFERROR(__xludf.DUMMYFUNCTION("""COMPUTED_VALUE"""),44712.0) -> 44712 | L4: =IFERROR(__xludf.DUMMYFUNCTION("""COMPUTED_VALUE"""),45801.0) -> 45801 | M4: =IFERROR(__xludf.DUMMYFUNCTION("""COMPUTED_VALUE"""),"есть") -> есть
A5: =IFERROR(__xludf.DUMMYFUNCTION("""COMPUTED_VALUE"""),4.0) -> 4 | B5: =IFERROR(__xludf.DUMMYFUNCTION("""COMPUTED_VALUE"""),"BCG_M_Gamaleya") -> BCG_M_Gamaleya | C5: =IFERROR(__xludf.DUMMYFUNCTION("""COMPUTED_VALUE"""),"https://grls.rosminzdrav.ru/Grls_View_v2.aspx?routingGuid=30fc01db-b288-495f-9e55-e1dd798d18a9") -> https://grls.rosminzdrav.ru/Grls_View_v2.aspx?routingGuid=30fc01db-b288-495f-9e55-e1dd798d18a9 | D5: =IFERROR(__xludf.DUMMYFUNCTION("""COMPUTED_VALUE"""),"БЦЖ-М (Гамалеи)") -> БЦЖ-М (Гамалеи) | E5: =IFERROR(__xludf.DUMMYFUNCTION("""COMPUTED_VALUE"""),"Вакцина туберкулезная для щадящей первичной иммунизации (БЦЖ-М)") -> Вакцина туберкулезная для щадящей первичной иммунизации (БЦЖ-М) | F5: =IFERROR(__xludf.DUMMYFUNCTION("""COMPUTED_VALUE"""),"НИЦЭМ им. Н.Ф. Гамалеи") -> НИЦЭМ им. Н.Ф. Гамалеи | G5: =IFERROR(__xludf.DUMMYFUNCTION("""COMPUTED_VALUE"""),"in use") -> in use | H5: =IFERROR(__xludf.DUMMYFUNCTION("""COMPUTED_VALUE"""),"<p>Используется по умолчанию для вакцинации детей против туберкулеза. Однако на территориях с повышенной заболеваемостью туберкулезом, а также если в окружении новорожденного есть больной туберкулезом, используется другая вакцина — ""БЦЖ"".</p>") -> <p>Используется по умолчанию для вакцинации детей против туберкулеза. Однако на территориях с повышенной заболеваемостью туберкулезом, а также если в окружении новорожденного есть больной туберкулезом, используется другая вакцина — "БЦЖ".</p> | I5: =IFERROR(__xludf.DUMMYFUNCTION("""COMPUTED_VALUE"""),"Используется по умолчанию для вакцинации детей против туберкулеза. Однако на территориях с повышенной заболеваемостью туберкулезом, а также если в окружении новорожденного есть больной туберкулезом, используется другая вакцина — ""БЦЖ"".") -> Используется по умолчанию для вакцинации детей против туберкулеза. Однако на территориях с повышенной заболеваемостью туберкулезом, а также если в окружении новорожденного есть больной туберкулезом, используется другая вакцина — "БЦЖ". | J5: =IFERROR(__xludf.DUMMYFUNCTION("""COMPUTED_VALUE"""),0.025) -> 0.025 | K5: =IFERROR(__xludf.DUMMYFUNCTION("""COMPUTED_VALUE"""),44712.0) -> 44712 | L5: =IFERROR(__xludf.DUMMYFUNCTION("""COMPUTED_VALUE"""),45818.0) -> 45818 | M5: =IFERROR(__xludf.DUMMYFUNCTION("""COMPUTED_VALUE"""),"есть") -> есть
A6: =IFERROR(__xludf.DUMMYFUNCTION("""COMPUTED_VALUE"""),5.0) -> 5 | B6: =IFERROR(__xludf.DUMMYFUNCTION("""COMPUTED_VALUE"""),"Infanrix") -> Infanrix | C6: =IFERROR(__xludf.DUMMYFUNCTION("""COMPUTED_VALUE"""),"https://grls.rosminzdrav.ru/Grls_View_v2.aspx?routingGuid=60b8bad6-1fec-492d-a07c-25eee3daa0b5") -> https://grls.rosminzdrav.ru/Grls_View_v2.aspx?routingGuid=60b8bad6-1fec-492d-a07c-25eee3daa0b5 | D6: =IFERROR(__xludf.DUMMYFUNCTION("""COMPUTED_VALUE"""),"Инфанрикс") -> Инфанрикс | E6: =IFERROR(__xludf.DUMMYFUNCTION("""COMPUTED_VALUE"""),"Инфанрикс® (Вакцина для профилактики дифтерии, столбняка, коклюша (бесклеточная) трехкомпонентная адсорбированная жидкая)") -> Инфанрикс® (Вакцина для профилактики дифтерии, столбняка, коклюша (бесклеточная) трехкомпонентная адсорбированная жидкая) | F6: =IFERROR(__xludf.DUMMYFUNCTION("""COMPUTED_VALUE"""),"GSK") -> GSK | G6: =IFERROR(__xludf.DUMMYFUNCTION("""COMPUTED_VALUE"""),"not in use") -> not in use | H6: =IFERROR(__xludf.DUMMYFUNCTION("""COMPUTED_VALUE"""),"<p>DTaP, бесклеточный коклюшный компонент</p>") -> <p>DTaP, бесклеточный коклюшный компонент</p> | I6: =IFERROR(__xludf.DUMMYFUNCTION("""COMPUTED_VALUE"""),"DTaP, бесклеточный коклюшный компонент") -> DTaP, бесклеточный коклюшный компонент | J6: =IFERROR(__xludf.DUMMYFUNCTION("""COMPUTED_VALUE"""),0.5) -> 0.5 | K6: =IFERROR(__xludf.DUMMYFUNCTION("""COMPUTED_VALUE"""),44712.0) -> 44712 | L6: =IFERROR(__xludf.DUMMYFUNCTION("""COMPUTED_VALUE"""),45689.0) -> 45689 | M6: =IFERROR(__xludf.DUMMYFUNCTION("""COMPUTED_VALUE"""),"есть") -> есть
A7: =IFERROR(__xludf.DUMMYFUNCTION("""COMPUTED_VALUE"""),6.0) -> 6 | B7: =IFERROR(__xludf.DUMMYFUNCTION("""COMPUTED_VALUE"""),"AKDS_Microgen") -> AKDS_Microgen | C7: =IFERROR(__xludf.DUMMYFUNCTION("""COMPUTED_VALUE"""),"https://grls.rosminzdrav.ru/Grls_View_v2.aspx?routingGuid=73faea00-ddd0-427e-9f40-49dfea9a2470") -> https://grls.rosminzdrav.ru/Grls_View_v2.aspx?routingGuid=73faea00-ddd0-427e-9f40-49dfea9a2470 | D7: =IFERROR(__xludf.DUMMYFUNCTION("""COMPUTED_VALUE"""),"АКДС (Микроген)") -> АКДС (Микроген) | E7: =IFERROR(__xludf.DUMMYFUNCTION("""COMPUTED_VALUE"""),"Вакцина коклюшно-дифтерийно-столбнячная адсорбированная (АКДС-вакцина)") -> Вакцина коклюшно-дифтерийно-столбнячная адсорбированная (АКДС-вакцина) | F7: =IFERROR(__xludf.DUMMYFUNCTION("""COMPUTED_VALUE"""),"Микроген") -> Микроген | G7: =IFERROR(__xludf.DUMMYFUNCTION("""COMPUTED_VALUE"""),"in use") -> in use | H7: =IFERROR(__xludf.DUMMYFUNCTION("""COMPUTED_VALUE"""),"<p>DTaP, цельноклеточный коклюшный компонент</p>") -> <p>DTaP, цельноклеточный коклюшный компонент</p> | I7: =IFERROR(__xludf.DUMMYFUNCTION("""COMPUTED_VALUE"""),"DTaP, цельноклеточный коклюшный компонент") -> DTaP, цельноклеточный коклюшный компонент | J7: =IFERROR(__xludf.DUMMYFUNCTION("""COMPUTED_VALUE"""),0.5) -> 0.5 | K7: =IFERROR(__xludf.DUMMYFUNCTION("""COMPUTED_VALUE"""),44712.0) -> 44712 | L7: =IFERROR(__xludf.DUMMYFUNCTION("""COMPUTED_VALUE"""),45689.0) -> 45689 | M7: =IFERROR(__xludf.DUMMYFUNCTION("""COMPUTED_VALUE"""),"есть") -> есть
A8: =IFERROR(__xludf.DUMMYFUNCTION("""COMPUTED_VALUE"""),7.0) -> 7 | B8: =IFERROR(__xludf.DUMMYFUNCTION("""COMPUTED_VALUE"""),"AKDS_Biomed") -> AKDS_Biomed | C8: =IFERROR(__xludf.DUMMYFUNCTION("""COMPUTED_VALUE"""),"https://grls.rosminzdrav.ru/Grls_View_v2.aspx?routingGuid=aba4f9bd-407e-42a8-a32c-1105beece2f6") -> https://grls.rosminzdrav.ru/Grls_View_v2.aspx?routingGuid=aba4f9bd-407e-42a8-a32c-1105beece2f6 | D8: =IFERROR(__xludf.DUMMYFUNCTION("""COMPUTED_VALUE"""),"АКДС (Биомед)") -> АКДС (Биомед) | E8: =IFERROR(__xludf.DUMMYFUNCTION("""COMPUTED_VALUE"""),"Вакцина коклюшно-дифтерийно-столбнячная адсорбированная (АКДС-вакцина)") -> Вакцина коклюшно-дифтерийно-столбнячная адсорбированная (АКДС-вакцина) | F8: =IFERROR(__xludf.DUMMYFUNCTION("""COMPUTED_VALUE"""),"Биомед") -> Биомед | G8: =IFERROR(__xludf.DUMMYFUNCTION("""COMPUTED_VALUE"""),"in use") -> in use | H8: =IFERROR(__xludf.DUMMYFUNCTION("""COMPUTED_VALUE"""),"<p>DTaP, цельноклеточный коклюшный компонент</p>") -> <p>DTaP, цельноклеточный коклюшный компонент</p> | I8: =IFERROR(__xludf.DUMMYFUNCTION("""COMPUTED_VALUE"""),"DTaP, цельноклеточный коклюшный компонент") -> DTaP, цельноклеточный коклюшный компонент | J8: =IFERROR(__xludf.DUMMYFUNCTION("""COMPUTED_VALUE"""),0.5) -> 0.5 | K8: =IFERROR(__xludf.DUMMYFUNCTION("""COMPUTED_VALUE"""),44712.0) -> 44712 | L8: =IFERROR(__xludf.DUMMYFUNCTION("""COMPUTED_VALUE"""),45079.0) -> 45079 | M8: =IFERROR(__xludf.DUMMYFUNCTION("""COMPUTED_VALUE"""),"нет") -> нет
A9: =IFERROR(__xludf.DUMMYFUNCTION("""COMPUTED_VALUE"""),8.0) -> 8 | B9: =IFERROR(__xludf.DUMMYFUNCTION("""COMPUTED_VALUE"""),"Bubo_kok") -> Bubo_kok | C9: =IFERROR(__xludf.DUMMYFUNCTION("""COMPUTED_VALUE"""),"https://grls.rosminzdrav.ru/Grls_View_v2.aspx?routingGuid=81b39c46-e795-4993-b85b-0cf51e164f6b") -> https://grls.rosminzdrav.ru/Grls_View_v2.aspx?routingGuid=81b39c46-e795-4993-b85b-0cf51e164f6b | D9: =IFERROR(__xludf.DUMMYFUNCTION("""COMPUTED_VALUE"""),"Бубо-Кок") -> Бубо-Кок | E9: =IFERROR(__xludf.DUMMYFUNCTION("""COMPUTED_VALUE"""),"Бубо®-Кок") -> Бубо®-Кок | F9: =IFERROR(__xludf.DUMMYFUNCTION("""COMPUTED_VALUE"""),"Комбиотех") -> Комбиотех | G9: =IFERROR(__xludf.DUMMYFUNCTION("""COMPUTED_VALUE"""),"not in use") -> not in use | J9: =IFERROR(__xludf.DUMMYFUNCTION("""COMPUTED_VALUE"""),0.5) -> 0.5 | K9: =IFERROR(__xludf.DUMMYFUNCTION("""COMPUTED_VALUE"""),44712.0) -> 44712 | L9: =IFERROR(__xludf.DUMMYFUNCTION("""COMPUTED_VALUE"""),44712.0) -> 44712 | M9: =IFERROR(__xludf.DUMMYFUNCTION("""COMPUTED_VALUE"""),"нет") -> нет
A10: =IFERROR(__xludf.DUMMYFUNCTION("""COMPUTED_VALUE"""),9.0) -> 9 | B10: =IFERROR(__xludf.DUMMYFUNCTION("""COMPUTED_VALUE"""),"Pentaxim") -> Pentaxim | C10: =IFERROR(__xludf.DUMMYFUNCTION("""COMPUTED_VALUE"""),"https://grls.rosminzdrav.ru/Grls_View_v2.aspx?routingGuid=04b887e5-95d7-44df-beaa-a539fe956444") -> https://grls.rosminzdrav.ru/Grls_View_v2.aspx?routingGuid=04b887e5-95d7-44df-beaa-a539fe956444 | D10: =IFERROR(__xludf.DUMMYFUNCTION("""COMPUTED_VALUE"""),"Пентаксим") -> Пентаксим | E10: =IFERROR(__xludf.DUMMYFUNCTION("""COMPUTED_VALUE"""),"Пентаксим® (вакцина для профилактики дифтерии и столбняка адсорбированная, коклюша ацеллюлярная, полиомиелита инактивированная и инфекций, вызываемых Haemophilus influenzae тип b, конъюгированная)") -> Пентаксим® (вакцина для профилактики дифтерии и столбняка адсорбированная, коклюша ацеллюлярная, полиомиелита инактивированная и инфекций, вызываемых Haemophilus influenzae тип b, конъюгированная) | F10: =IFERROR(__xludf.DUMMYFUNCTION("""COMPUTED_VALUE"""),"Sanofi Pasteur") -> Sanofi Pasteur | G10: =IFERROR(__xludf.DUMMYFUNCTION("""COMPUTED_VALUE"""),"in use") -> in use | H10: =IFERROR(__xludf.DUMMYFUNCTION("""COMPUTED_VALUE"""),"<p>DTaP-IPV-Hib, бесклеточный коклюшный компонент</p>") -> <p>DTaP-IPV-Hib, бесклеточный коклюшный компонент</p> | I10: =IFERROR(__xludf.DUMMYFUNCTION("""COMPUTED_VALUE"""),"DTaP-IPV-Hib, бесклеточный коклюшный компонент") -> DTaP-IPV-Hib, бесклеточный коклюшный компонент | J10: =IFERROR(__xludf.DUMMYFUNCTION("""COMPUTED_VALUE"""),0.5) -> 0.5 | K10: =IFERROR(__xludf.DUMMYFUNCTION("""COMPUTED_VALUE"""),44712.0) -> 44712 | L10: =IFERROR(__xludf.DUMMYFUNCTION("""COMPUTED_VALUE"""),46204.0) -> 46204 | M10: =IFERROR(__xludf.DUMMYFUNCTION("""COMPUTED_VALUE"""),"есть") -> есть
A11: =IFERROR(__xludf.DUMMYFUNCTION("""COMPUTED_VALUE"""),10.0) -> 10 | B11: =IFERROR(__xludf.DUMMYFUNCTION("""COMPUTED_VALUE"""),"Infanrix_Hexa") -> Infanrix_Hexa | C11: =IFERROR(__xludf.DUMMYFUNCTION("""COMPUTED_VALUE"""),"https://grls.rosminzdrav.ru/Grls_View_v2.aspx?routingGuid=f9454b06-083d-4c13-8eda-e54a19450d13") -> https://grls.rosminzdrav.ru/Grls_View_v2.aspx?routingGuid=f9454b06-083d-4c13-8eda-e54a19450d13 | D11: =IFERROR(__xludf.DUMMYFUNCTION("""COMPUTED_VALUE"""),"Инфанрикс Гекса") -> Инфанрикс Гекса | E11: =IFERROR(__xludf.DUMMYFUNCTION("""COMPUTED_VALUE"""),"Инфанрикс® Гекса (Вакцина для профилактики дифтерии, столбняка, коклюша (бесклеточная), полиомиелита (инактивированная), гепатита B комбинированная, адсорбированная в комплекте с вакциной для профилактики инфекции, вызываемой Haemophilus influenzae тип b "&"конъюгированной, адсорбированной)") -> Инфанрикс® Гекса (Вакцина для профилактики дифтерии, столбняка, коклюша (бесклеточная), полиомиелита (инактивированная), гепатита B комбинированная, адсорбированная в комплекте с вакциной для профилактики инфекции, вызываемой Haemophilus influenzae тип b конъюгированной, адсорбированной) | F11: =IFERROR(__xludf.DUMMYFUNCTION("""COMPUTED_VALUE"""),"GSK") -> GSK | G11: =IFERROR(__xludf.DUMMYFUNCTION("""COMPUTED_VALUE"""),"in use") -> in use | H11: =IFERROR(__xludf.DUMMYFUNCTION("""COMPUTED_VALUE"""),"<p>DTaP-IPV-Hib-HepB, бесклеточный коклюшный компонент</p>") -> <p>DTaP-IPV-Hib-HepB, бесклеточный коклюшный компонент</p> | I11: =IFERROR(__xludf.DUMMYFUNCTION("""COMPUTED_VALUE"""),"DTaP-IPV-Hib-HepB, бесклеточный коклюшный компонент") -> DTaP-IPV-Hib-HepB, бесклеточный коклюшный компонент | J11: =IFERROR(__xludf.DUMMYFUNCTION("""COMPUTED_VALUE"""),0.5) -> 0.5 | K11: =IFERROR(__xludf.DUMMYFUNCTION("""COMPUTED_VALUE"""),44712.0) -> 44712 | L11: =IFERROR(__xludf.DUMMYFUNCTION("""COMPUTED_VALUE"""),46000.0) -> 46000 | M11: =IFERROR(__xludf.DUMMYFUNCTION("""COMPUTED_VALUE"""),"есть") -> есть
A12: =IFERROR(__xludf.DUMMYFUNCTION("""COMPUTED_VALUE"""),11.0) -> 11 | B12: =IFERROR(__xludf.DUMMYFUNCTION("""COMPUTED_VALUE"""),"Bubo_M") -> Bubo_M | C12: =IFERROR(__xludf.DUMMYFUNCTION("""COMPUTED_VALUE"""),"https://grls.rosminzdrav.ru/Grls_View_v2.aspx?routingGuid=0b7d30f1-b40f-453c-9c7b-800a072aa409") -> https://grls.rosminzdrav.ru/Grls_View_v2.aspx?routingGuid=0b7d30f1-b40f-453c-9c7b-800a072aa409 | D12: =IFERROR(__xludf.DUMMYFUNCTION("""COMPUTED_VALUE"""),"Бубо-М") -> Бубо-М | E12: =IFERROR(__xludf.DUMMYFUNCTION("""COMPUTED_VALUE"""),"Бубо®-М (Вакцина комбинированная гепатита B и анатоксина дифтерийно-столбнячного с уменьшенным содержанием антигенов адсорбированная жидкая)") -> Бубо®-М (Вакцина комбинированная гепатита B и анатоксина дифтерийно-столбнячного с уменьшенным содержанием антигенов адсорбированная жидкая) | F12: =IFERROR(__xludf.DUMMYFUNCTION("""COMPUTED_VALUE"""),"Комбиотех") -> Комбиотех | G12: =IFERROR(__xludf.DUMMYFUNCTION("""COMPUTED_VALUE"""),"not in use") -> not in use | J12: =IFERROR(__xludf.DUMMYFUNCTION("""COMPUTED_VALUE"""),0.5) -> 0.5 | K12: =IFERROR(__xludf.DUMMYFUNCTION("""COMPUTED_VALUE"""),44712.0) -> 44712 | L12: =IFERROR(__xludf.DUMMYFUNCTION("""COMPUTED_VALUE"""),46188.0) -> 46188 | M12: =IFERROR(__xludf.DUMMYFUNCTION("""COMPUTED_VALUE"""),"есть") -> есть
A13: =IFERROR(__xludf.DUMMYFUNCTION("""COMPUTED_VALUE"""),12.0) -> 12 | B13: =IFERROR(__xludf.DUMMYFUNCTION("""COMPUTED_VALUE"""),"AD_M_Microgen") -> AD_M_Microgen | C13: =IFERROR(__xludf.DUMMYFUNCTION("""COMPUTED_VALUE"""),"https://grls.rosminzdrav.ru/Grls_View_v2.aspx?routingGuid=fa42329f-9433-4dc6-af8a-f811be13fb87") -> https://grls.rosminzdrav.ru/Grls_View_v2.aspx?routingGuid=fa42329f-9433-4dc6-af8a-f811be13fb87 | D13: =IFERROR(__xludf.DUMMYFUNCTION("""COMPUTED_VALUE"""),"АД-М (Микроген)") -> АД-М (Микроген) | E13: =IFERROR(__xludf.DUMMYFUNCTION("""COMPUTED_VALUE"""),"Анатоксин дифтерийный очищенный адсорбированный с уменьшенным содержанием антигена жидкий (АД-М-анатоксин)") -> Анатоксин дифтерийный очищенный адсорбированный с уменьшенным содержанием антигена жидкий (АД-М-анатоксин) | F13: =IFERROR(__xludf.DUMMYFUNCTION("""COMPUTED_VALUE"""),"Микроген") -> Микроген | G13: =IFERROR(__xludf.DUMMYFUNCTION("""COMPUTED_VALUE"""),"in use") -> in use | J13: =IFERROR(__xludf.DUMMYFUNCTION("""COMPUTED_VALUE"""),0.5) -> 0.5 | K13: =IFERROR(__xludf.DUMMYFUNCTION("""COMPUTED_VALUE"""),44712.0) -> 44712 | L13: =IFERROR(__xludf.DUMMYFUNCTION("""COMPUTED_VALUE"""),45689.0) -> 45689 | M13: =IFERROR(__xludf.DUMMYFUNCTION("""COMPUTED_VALUE"""),"https://lk.regmed.ru/Register/GetPDFfromDAToken?Token=9916a334-02fd-4f23-ad64-c996916ac2d6") -> https://lk.regmed.ru/Register/GetPDFfromDAToken?Token=9916a334-02fd-4f23-ad64-c996916ac2d6
A14: =IFERROR(__xludf.DUMMYFUNCTION("""COMPUTED_VALUE"""),13.0) -> 13 | B14: =IFERROR(__xludf.DUMMYFUNCTION("""COMPUTED_VALUE"""),"ADS_Microgen") -> ADS_Microgen | C14: =IFERROR(__xludf.DUMMYFUNCTION("""COMPUTED_VALUE"""),"https://grls.rosminzdrav.ru/Grls_View_v2.aspx?routingGuid=82af2230-6ada-4cb2-a263-0a2c1f841be2") -> https://grls.rosminzdrav.ru/Grls_View_v2.aspx?routingGuid=82af2230-6ada-4cb2-a263-0a2c1f841be2 | D14: =IFERROR(__xludf.DUMMYFUNCTION("""COMPUTED_VALUE"""),"АДС (Микроген)") -> АДС (Микроген) | E14: =IFERROR(__xludf.DUMMYFUNCTION("""COMPUTED_VALUE"""),"Анатоксин дифтерийно-столбнячный очищенный адсорбированный жидкий (АДС-анатоксин)") -> Анатоксин дифтерийно-столбнячный очищенный адсорбированный жидкий (АДС-анатоксин) | F14: =IFERROR(__xludf.DUMMYFUNCTION("""COMPUTED_VALUE"""),"Микроген") -> Микроген | G14: =IFERROR(__xludf.DUMMYFUNCTION("""COMPUTED_VALUE"""),"in use") -> in use | J14: =IFERROR(__xludf.DUMMYFUNCTION("""COMPUTED_VALUE"""),0.5) -> 0.5 | K14: =IFERROR(__xludf.DUMMYFUNCTION("""COMPUTED_VALUE"""),44712.0) -> 44712 | L14: =IFERROR(__xludf.DUMMYFUNCTION("""COMPUTED_VALUE"""),45689.0) -> 45689 | M14: =IFERROR(__xludf.DUMMYFUNCTION("""COMPUTED_VALUE"""),"https://lk.regmed.ru/Register/GetPDFfromDAToken?Token=ff0cddac-c2c3-4fac-84e2-d026f4f71869") -> https://lk.regmed.ru/Register/GetPDFfromDAToken?Token=ff0cddac-c2c3-4fac-84e2-d026f4f71869
A15: =IFERROR(__xludf.DUMMYFUNCTION("""COMPUTED_VALUE"""),14.0) -> 14 | B15: =IFERROR(__xludf.DUMMYFUNCTION("""COMPUTED_VALUE"""),"ADS_M_Microgen") -> ADS_M_Microgen | C15: =IFERROR(__xludf.DUMMYFUNCTION("""COMPUTED_VALUE"""),"https://grls.rosminzdrav.ru/Grls_View_v2.aspx?routingGuid=7901c857-1397-49d2-9a93-f8c171091efa") -> https://grls.rosminzdrav.ru/Grls_View_v2.aspx?routingGuid=7901c857-1397-49d2-9a93-f8c171091efa | D15: =IFERROR(__xludf.DUMMYFUNCTION("""COMPUTED_VALUE"""),"АДС-М (Микроген)") -> АДС-М (Микроген) | E15: =IFERROR(__xludf.DUMMYFUNCTION("""COMPUTED_VALUE"""),"Анатоксин дифтерийно-столбнячный очищенный адсорбированный с уменьшенным содержанием антигенов жидкий (АДС-М-анатоксин)") -> Анатоксин дифтерийно-столбнячный очищенный адсорбированный с уменьшенным содержанием антигенов жидкий (АДС-М-анатоксин) | F15: =IFERROR(__xludf.DUMMYFUNCTION("""COMPUTED_VALUE"""),"Микроген") -> Микроген | G15: =IFERROR(__xludf.DUMMYFUNCTION("""COMPUTED_VALUE"""),"in use") -> in use | J15: =IFERROR(__xludf.DUMMYFUNCTION("""COMPUTED_VALUE"""),0.5) -> 0.5 | K15: =IFERROR(__xludf.DUMMYFUNCTION("""COMPUTED_VALUE"""),44712.0) -> 44712 | L15: =IFERROR(__xludf.DUMMYFUNCTION("""COMPUTED_VALUE"""),45861.0) -> 45861 | M15: =IFERROR(__xludf.DUMMYFUNCTION("""COMPUTED_VALUE"""),"https://lk.regmed.ru/Register/GetPDFfromDAToken?Token=67df064e-3139-49b6-917f-a5131fbd35d6") -> https://lk.regmed.ru/Register/GetPDFfromDAToken?Token=67df064e-3139-49b6-917f-a5131fbd35d6
A16: =IFERROR(__xludf.DUMMYFUNCTION("""COMPUTED_VALUE"""),15.0) -> 15 | B16: =IFERROR(__xludf.DUMMYFUNCTION("""COMPUTED_VALUE"""),"ADS_M_Biomed") -> ADS_M_Biomed | C16: =IFERROR(__xludf.DUMMYFUNCTION("""COMPUTED_VALUE"""),"https://grls.rosminzdrav.ru/Grls_View_v2.aspx?routingGuid=795940d7 – 9c11-423c-98fe-44a1d739a593") -> https://grls.rosminzdrav.ru/Grls_View_v2.aspx?routingGuid=795940d7 – 9c11-423c-98fe-44a1d739a593 | D16: =IFERROR(__xludf.DUMMYFUNCTION("""COMPUTED_VALUE"""),"АДС-М (Биомед)") -> АДС-М (Биомед) | E16: =IFERROR(__xludf.DUMMYFUNCTION("""COMPUTED_VALUE"""),"Анатоксин дифтерийно-столбнячный очищенный адсорбированный с уменьшенным содержанием антигенов жидкий (АДС-М анатоксин)") -> Анатоксин дифтерийно-столбнячный очищенный адсорбированный с уменьшенным содержанием антигенов жидкий (АДС-М анатоксин) | F16: =IFERROR(__xludf.DUMMYFUNCTION("""COMPUTED_VALUE"""),"Биомед") -> Биомед | G16: =IFERROR(__xludf.DUMMYFUNCTION("""COMPUTED_VALUE"""),"in use") -> in use | J16: =IFERROR(__xludf.DUMMYFUNCTION("""COMPUTED_VALUE"""),0.5) -> 0.5 | K16: =IFERROR(__xludf.DUMMYFUNCTION("""COMPUTED_VALUE"""),44712.0) -> 44712 | L16: =IFERROR(__xludf.DUMMYFUNCTION("""COMPUTED_VALUE"""),44712.0) -> 44712 | M16: =IFERROR(__xludf.DUMMYFUNCTION("""COMPUTED_VALUE"""),"нет") -> нет
A17: =IFERROR(__xludf.DUMMYFUNCTION("""COMPUTED_VALUE"""),16.0) -> 16 | B17: =IFERROR(__xludf.DUMMYFUNCTION("""COMPUTED_VALUE"""),"Adacel") -> Adacel | C17: =IFERROR(__xludf.DUMMYFUNCTION("""COMPUTED_VALUE"""),"https://grls.rosminzdrav.ru/Grls_View_v2.aspx?routingGuid=d8627a3c-16a5-46d0-b31f-e60eb2448d80") -> https://grls.rosminzdrav.ru/Grls_View_v2.aspx?routingGuid=d8627a3c-16a5-46d0-b31f-e60eb2448d80 | D17: =IFERROR(__xludf.DUMMYFUNCTION("""COMPUTED_VALUE"""),"Адасель") -> Адасель | E17: =IFERROR(__xludf.DUMMYFUNCTION("""COMPUTED_VALUE"""),"АДАСЕЛЬ® [Вакцина для профилактики дифтерии (с уменьшенным содержанием антигена), коклюша (с уменьшенным содержанием антигена, бесклеточная) и столбняка, комбинированная, адсорбированная]") -> АДАСЕЛЬ® [Вакцина для профилактики дифтерии (с уменьшенным содержанием антигена), коклюша (с уменьшенным содержанием антигена, бесклеточная) и столбняка, комбинированная, адсорбированная] | F17: =IFERROR(__xludf.DUMMYFUNCTION("""COMPUTED_VALUE"""),"Санофи Пастер Лимитед") -> Санофи Пастер Лимитед | G17: =IFERROR(__xludf.DUMMYFUNCTION("""COMPUTED_VALUE"""),"in use") -> in use | H17: =IFERROR(__xludf.DUMMYFUNCTION("""COMPUTED_VALUE"""),"<p>Tdap, сниженное содержание дифтерийного и коклюшного компонента, бесклеточный коклюшный компонент</p>") -> <p>Tdap, сниженное содержание дифтерийного и коклюшного компонента, бесклеточный коклюшный компонент</p> | I17: =IFERROR(__xludf.DUMMYFUNCTION("""COMPUTED_VALUE"""),"Tdap, сниженное содержание дифтерийного и коклюшного компонента, бесклеточный коклюшный компонент") -> Tdap, сниженное содержание дифтерийного и коклюшного компонента, бесклеточный коклюшный компонент | J17: =IFERROR(__xludf.DUMMYFUNCTION("""COMPUTED_VALUE"""),0.5) -> 0.5 | K17: =IFERROR(__xludf.DUMMYFUNCTION("""COMPUTED_VALUE"""),44712.0) -> 44712 | L17: =IFERROR(__xludf.DUMMYFUNCTION("""COMPUTED_VALUE"""),45689.0) -> 45689 | M17: =IFERROR(__xludf.DUMMYFUNCTION("""COMPUTED_VALUE"""),"https://lk.regmed.ru/Register/GetPDFfromDAToken?Token=7fabfdf2-4fe8-448e-859f-9a4b20cc3213") -> https://lk.regmed.ru/Register/GetPDFfromDAToken?Token=7fabfdf2-4fe8-448e-859f-9a4b20cc3213
A18: =IFERROR(__xludf.DUMMYFUNCTION("""COMPUTED_VALUE"""),17.0) -> 17 | B18: =IFERROR(__xludf.DUMMYFUNCTION("""COMPUTED_VALUE"""),"Algavac_M") -> Algavac_M | C18: =IFERROR(__xludf.DUMMYFUNCTION("""COMPUTED_VALUE"""),"https://grls.rosminzdrav.ru/Grls_View_v2.aspx?routingGuid=2bf12380-3a71-4642-a9a3-ef0e4ca9b815") -> https://grls.rosminzdrav.ru/Grls_View_v2.aspx?routingGuid=2bf12380-3a71-4642-a9a3-ef0e4ca9b815 | D18: =IFERROR(__xludf.DUMMYFUNCTION("""COMPUTED_VALUE"""),"Альгавак М") -> Альгавак М | E18: =IFERROR(__xludf.DUMMYFUNCTION("""COMPUTED_VALUE"""),"АЛЬГАВАК® М") -> АЛЬГАВАК® М | G18: =IFERROR(__xludf.DUMMYFUNCTION("""COMPUTED_VALUE"""),"in use") -> in use | K18: =IFERROR(__xludf.DUMMYFUNCTION("""COMPUTED_VALUE"""),44712.0) -> 44712 | L18: =IFERROR(__xludf.DUMMYFUNCTION("""COMPUTED_VALUE"""),45715.0) -> 45715 | M18: =IFERROR(__xludf.DUMMYFUNCTION("""COMPUTED_VALUE"""),"нет") -> нет
A19: =IFERROR(__xludf.DUMMYFUNCTION("""COMPUTED_VALUE"""),18.0) -> 18 | B19: =IFERROR(__xludf.DUMMYFUNCTION("""COMPUTED_VALUE"""),"Algavac") -> Algavac | C19: =IFERROR(__xludf.DUMMYFUNCTION("""COMPUTED_VALUE"""),"https://grls.rosminzdrav.ru/Grls_View_v2.aspx?routingGuid=4f6d874c-7745-4c6b-8c90-228a1f2f3484") -> https://grls.rosminzdrav.ru/Grls_View_v2.aspx?routingGuid=4f6d874c-7745-4c6b-8c90-228a1f2f3484 | D19: =IFERROR(__xludf.DUMMYFUNCTION("""COMPUTED_VALUE"""),"Альгавак") -> Альгавак | E19: =IFERROR(__xludf.DUMMYFUNCTION("""COMPUTED_VALUE"""),"АЛЬГАВАК®") -> АЛЬГАВАК® | G19: =IFERROR(__xludf.DUMMYFUNCTION("""COMPUTED_VALUE"""),"not in use") -> not in use | H19: =IFERROR(__xludf.DUMMYFUNCTION("""COMPUTED_VALUE"""),"<p>Вакцину АЛЬГАВАК можно использовать для ревакцинации в тех случаях, когда предыдущая вакцинация осуществлялась другими инактивированными вакцинами для профилактики гепатита А.</p>") -> <p>Вакцину АЛЬГАВАК можно использовать для ревакцинации в тех случаях, когда предыдущая вакцинация осуществлялась другими инактивированными вакцинами для профилактики гепатита А.</p> | I19: =IFERROR(__xludf.DUMMYFUNCTION("""COMPUTED_VALUE"""),"Вакцину АЛЬГАВАК можно использовать для ревакцинации в тех случаях, когда предыдущая вакцинация осуществлялась другими инактивированными вакцинами для профилактики гепатита А.") -> Вакцину АЛЬГАВАК можно использовать для ревакцинации в тех случаях, когда предыдущая вакцинация осуществлялась другими инактивированными вакцинами для профилактики гепатита А. | K19: =IFERROR(__xludf.DUMMYFUNCTION("""COMPUTED_VALUE"""),44712.0) -> 44712 | L19: =IFERROR(__xludf.DUMMYFUNCTION("""COMPUTED_VALUE"""),46188.0) -> 46188 | M19: =IFERROR(__xludf.DUMMYFUNCTION("""COMPUTED_VALUE"""),"есть") -> есть
A20: =IFERROR(__xludf.DUMMYFUNCTION("""COMPUTED_VALUE"""),19.0) -> 19 | B20: =IFERROR(__xludf.DUMMYFUNCTION("""COMPUTED_VALUE"""),"Havrix_720") -> Havrix_720 | C20: =IFERROR(__xludf.DUMMYFUNCTION("""COMPUTED_VALUE"""),"https://grls.rosminzdrav.ru/Grls_View_v2.aspx?routingGuid=b8dfef4d-a4cf-4d18-9599-1a3fb42864c7") -> https://grls.rosminzdrav.ru/Grls_View_v2.aspx?routingGuid=b8dfef4d-a4cf-4d18-9599-1a3fb42864c7 | D20: =IFERROR(__xludf.DUMMYFUNCTION("""COMPUTED_VALUE"""),"Хаврикс 720") -> Хаврикс 720 | E20: =IFERROR(__xludf.DUMMYFUNCTION("""COMPUTED_VALUE"""),"Хаврикс® (вакцина против гепатита А инактивированная)") -> Хаврикс® (вакцина против гепатита А инактивированная) | F20: =IFERROR(__xludf.DUMMYFUNCTION("""COMPUTED_VALUE"""),"GSK") -> GSK | G20: =IFERROR(__xludf.DUMMYFUNCTION("""COMPUTED_VALUE"""),"in use") -> in use | K20: =IFERROR(__xludf.DUMMYFUNCTION("""COMPUTED_VALUE"""),44712.0) -> 44712 | L20: =IFERROR(__xludf.DUMMYFUNCTION("""COMPUTED_VALUE"""),45689.0) -> 45689 | M20: =IFERROR(__xludf.DUMMYFUNCTION("""COMPUTED_VALUE"""),"https://lk.regmed.ru/Register/GetPDFfromDAToken?Token=6d0a7c06-3859-4f01-8d37-bf8887046a88") -> https://lk.regmed.ru/Register/GetPDFfromDAToken?Token=6d0a7c06-3859-4f01-8d37-bf8887046a88
A21: =IFERROR(__xludf.DUMMYFUNCTION("""COMPUTED_VALUE"""),20.0) -> 20 | B21: =IFERROR(__xludf.DUMMYFUNCTION("""COMPUTED_VALUE"""),"Havrix_1440") -> Havrix_1440 | C21: =IFERROR(__xludf.DUMMYFUNCTION("""COMPUTED_VALUE"""),"https://grls.rosminzdrav.ru/Grls_View_v2.aspx?routingGuid=b8dfef4d-a4cf-4d18-9599-1a3fb42864c7") -> https://grls.rosminzdrav.ru/Grls_View_v2.aspx?routingGuid=b8dfef4d-a4cf-4d18-9599-1a3fb42864c7 | D21: =IFERROR(__xludf.DUMMYFUNCTION("""COMPUTED_VALUE"""),"Хаврикс 1440") -> Хаврикс 1440 | E21: =IFERROR(__xludf.DUMMYFUNCTION("""COMPUTED_VALUE"""),"Хаврикс® (вакцина против гепатита А инактивированная)") -> Хаврикс® (вакцина против гепатита А инактивированная) | F21: =IFERROR(__xludf.DUMMYFUNCTION("""COMPUTED_VALUE"""),"GSK") -> GSK | G21: =IFERROR(__xludf.DUMMYFUNCTION("""COMPUTED_VALUE"""),"not in use") -> not in use | K21: =IFERROR(__xludf.DUMMYFUNCTION("""COMPUTED_VALUE"""),44712.0) -> 44712 | L21: =IFERROR(__xludf.DUMMYFUNCTION("""COMPUTED_VALUE"""),45689.0) -> 45689 | M21: =IFERROR(__xludf.DUMMYFUNCTION("""COMPUTED_VALUE"""),"https://lk.regmed.ru/Register/GetPDFfromDAToken?Token=6d0a7c06-3859-4f01-8d37-bf8887046a88") -> https://lk.regmed.ru/Register/GetPDFfromDAToken?Token=6d0a7c06-3859-4f01-8d37-bf8887046a88
A22: =IFERROR(__xludf.DUMMYFUNCTION("""COMPUTED_VALUE"""),21.0) -> 21 | B22: =IFERROR(__xludf.DUMMYFUNCTION("""COMPUTED_VALUE"""),"Avaxim_80") -> Avaxim_80 | C22: =IFERROR(__xludf.DUMMYFUNCTION("""COMPUTED_VALUE"""),"https://grls.rosminzdrav.ru/Grls_View_v2.aspx?routingGuid=0814c0aa-66c2-4566-a774-02de4c45b6ac") -> https://grls.rosminzdrav.ru/Grls_View_v2.aspx?routingGuid=0814c0aa-66c2-4566-a774-02de4c45b6ac | D22: =IFERROR(__xludf.DUMMYFUNCTION("""COMPUTED_VALUE"""),"Аваксим 80") -> Аваксим 80 | E22: =IFERROR(__xludf.DUMMYFUNCTION("""COMPUTED_VALUE"""),"Аваксим 80 (вакцина для профилактики гепатита A инактивированная, адсорбированная)") -> Аваксим 80 (вакцина для профилактики гепатита A инактивированная, адсорбированная) | G22: =IFERROR(__xludf.DUMMYFUNCTION("""COMPUTED_VALUE"""),"not in use") -> not in use | K22: =IFERROR(__xludf.DUMMYFUNCTION("""COMPUTED_VALUE"""),44712.0) -> 44712 | L22: =IFERROR(__xludf.DUMMYFUNCTION("""COMPUTED_VALUE"""),44916.0) -> 44916 | M22: =IFERROR(__xludf.DUMMYFUNCTION("""COMPUTED_VALUE"""),"нет") -> нет
A23: =IFERROR(__xludf.DUMMYFUNCTION("""COMPUTED_VALUE"""),22.0) -> 22 | B23: =IFERROR(__xludf.DUMMYFUNCTION("""COMPUTED_VALUE"""),"Avaxim_160") -> Avaxim_160 | C23: =IFERROR(__xludf.DUMMYFUNCTION("""COMPUTED_VALUE"""),"https://grls.rosminzdrav.ru/Grls_View_v2.aspx?routingGuid=658e07cb-fcb9-412f-9392-b9e9e21a6343") -> https://grls.rosminzdrav.ru/Grls_View_v2.aspx?routingGuid=658e07cb-fcb9-412f-9392-b9e9e21a6343 | D23: =IFERROR(__xludf.DUMMYFUNCTION("""COMPUTED_VALUE"""),"Аваксим 160") -> Аваксим 160 | E23: =IFERROR(__xludf.DUMMYFUNCTION("""COMPUTED_VALUE"""),"Аваксим 160 (вакцина для профилактики гепатита A инактивированная, адсорбированная)") -> Аваксим 160 (вакцина для профилактики гепатита A инактивированная, адсорбированная) | G23: =IFERROR(__xludf.DUMMYFUNCTION("""COMPUTED_VALUE"""),"not in use") -> not in use | K23: =IFERROR(__xludf.DUMMYFUNCTION("""COMPUTED_VALUE"""),44712.0) -> 44712 | L23: =IFERROR(__xludf.DUMMYFUNCTION("""COMPUTED_VALUE"""),44916.0) -> 44916 | M23: =IFERROR(__xludf.DUMMYFUNCTION("""COMPUTED_VALUE"""),"нет") -> нет
A24: =IFERROR(__xludf.DUMMYFUNCTION("""COMPUTED_VALUE"""),23.0) -> 23 | B24: =IFERROR(__xludf.DUMMYFUNCTION("""COMPUTED_VALUE"""),"Regevac_0_5") -> Regevac_0_5 | C24: =IFERROR(__xludf.DUMMYFUNCTION("""COMPUTED_VALUE"""),"https://grls.rosminzdrav.ru/Grls_View_v2.aspx?routingGuid=ec6e3b51-e76b-4abf-99cf-7c02bab06091") -> https://grls.rosminzdrav.ru/Grls_View_v2.aspx?routingGuid=ec6e3b51-e76b-4abf-99cf-7c02bab06091 | D24: =IFERROR(__xludf.DUMMYFUNCTION("""COMPUTED_VALUE"""),"Регевак детский") -> Регевак детский | E24: =IFERROR(__xludf.DUMMYFUNCTION("""COMPUTED_VALUE"""),"Регевак® В (Вакцина против гепатита В, рекомбинантная дрожжевая жидкая)") -> Регевак® В (Вакцина против гепатита В, рекомбинантная дрожжевая жидкая) | G24: =IFERROR(__xludf.DUMMYFUNCTION("""COMPUTED_VALUE"""),"in use") -> in use | K24: =IFERROR(__xludf.DUMMYFUNCTION("""COMPUTED_VALUE"""),44712.0) -> 44712 | L24: =IFERROR(__xludf.DUMMYFUNCTION("""COMPUTED_VALUE"""),45988.0) -> 45988 | M24: =IFERROR(__xludf.DUMMYFUNCTION("""COMPUTED_VALUE"""),"есть") -> есть
A25: =IFERROR(__xludf.DUMMYFUNCTION("""COMPUTED_VALUE"""),24.0) -> 24 | B25: =IFERROR(__xludf.DUMMYFUNCTION("""COMPUTED_VALUE"""),"HepB_Combiotech_0_5") -> HepB_Combiotech_0_5 | C25: =IFERROR(__xludf.DUMMYFUNCTION("""COMPUTED_VALUE"""),"https://grls.rosminzdrav.ru/Grls_View_v2.aspx?routingGuid=0cc60fe9-635e-4134-80d2-59a7787e33fb") -> https://grls.rosminzdrav.ru/Grls_View_v2.aspx?routingGuid=0cc60fe9-635e-4134-80d2-59a7787e33fb | D25: =IFERROR(__xludf.DUMMYFUNCTION("""COMPUTED_VALUE"""),"гепатита B (Комбиотех) детская") -> гепатита B (Комбиотех) детская | E25: =IFERROR(__xludf.DUMMYFUNCTION("""COMPUTED_VALUE"""),"Вакцина гепатита В рекомбинантная дрожжевая") -> Вакцина гепатита В рекомбинантная дрожжевая | F25: =IFERROR(__xludf.DUMMYFUNCTION("""COMPUTED_VALUE"""),"Комбиотех") -> Комбиотех | G25: =IFERROR(__xludf.DUMMYFUNCTION("""COMPUTED_VALUE"""),"in use") -> in use | H25: =IFERROR(__xludf.DUMMYFUNCTION("""COMPUTED_VALUE"""),"<p>Препарат выпускается в виде «взрослой» и «детской» вакцины с консервантом и без консерванта.</p>") -> <p>Препарат выпускается в виде «взрослой» и «детской» вакцины с консервантом и без консерванта.</p> | I25: =IFERROR(__xludf.DUMMYFUNCTION("""COMPUTED_VALUE"""),"Препарат выпускается в виде «взрослой» и «детской» вакцины с консервантом и без консерванта.") -> Препарат выпускается в виде «взрослой» и «детской» вакцины с консервантом и без консерванта. | K25: =IFERROR(__xludf.DUMMYFUNCTION("""COMPUTED_VALUE"""),44712.0) -> 44712 | L25: =IFERROR(__xludf.DUMMYFUNCTION("""COMPUTED_VALUE"""),46130.0) -> 46130 | M25: =IFERROR(__xludf.DUMMYFUNCTION("""COMPUTED_VALUE"""),"есть") -> есть
A26: =IFERROR(__xludf.DUMMYFUNCTION("""COMPUTED_VALUE"""),25.0) -> 25 | B26: =IFERROR(__xludf.DUMMYFUNCTION("""COMPUTED_VALUE"""),"Euvax_B_0_5") -> Euvax_B_0_5 | C26: =IFERROR(__xludf.DUMMYFUNCTION("""COMPUTED_VALUE"""),"https://grls.rosminzdrav.ru/Grls_View_v2.aspx?routingGuid=0d28b2ad-18b2-4e7a-8c27-436c0feea6d4") -> https://grls.rosminzdrav.ru/Grls_View_v2.aspx?routingGuid=0d28b2ad-18b2-4e7a-8c27-436c0feea6d4 | D26: =IFERROR(__xludf.DUMMYFUNCTION("""COMPUTED_VALUE"""),"Эувакс В детский") -> Эувакс В детский | E26: =IFERROR(__xludf.DUMMYFUNCTION("""COMPUTED_VALUE"""),"Эувакс В (вакцина для профилактики гепатита B рекомбинантная)") -> Эувакс В (вакцина для профилактики гепатита B рекомбинантная) | G26: =IFERROR(__xludf.DUMMYFUNCTION("""COMPUTED_VALUE"""),"not in use") -> not in use | K26: =IFERROR(__xludf.DUMMYFUNCTION("""COMPUTED_VALUE"""),44712.0) -> 44712 | L26: =IFERROR(__xludf.DUMMYFUNCTION("""COMPUTED_VALUE"""),44712.0) -> 44712 | M26: =IFERROR(__xludf.DUMMYFUNCTION("""COMPUTED_VALUE"""),"нет") -> нет
A27: =IFERROR(__xludf.DUMMYFUNCTION("""COMPUTED_VALUE"""),26.0) -> 26 | B27: =IFERROR(__xludf.DUMMYFUNCTION("""COMPUTED_VALUE"""),"Euvax_B_1_0") -> Euvax_B_1_0 | C27: =IFERROR(__xludf.DUMMYFUNCTION("""COMPUTED_VALUE"""),"https://grls.rosminzdrav.ru/Grls_View_v2.aspx?routingGuid=0d28b2ad-18b2-4e7a-8c27-436c0feea6d4") -> https://grls.rosminzdrav.ru/Grls_View_v2.aspx?routingGuid=0d28b2ad-18b2-4e7a-8c27-436c0feea6d4 | D27: =IFERROR(__xludf.DUMMYFUNCTION("""COMPUTED_VALUE"""),"Эувакс В взрослый") -> Эувакс В взрослый | E27: =IFERROR(__xludf.DUMMYFUNCTION("""COMPUTED_VALUE"""),"Эувакс В (вакцина для профилактики гепатита B рекомбинантная)") -> Эувакс В (вакцина для профилактики гепатита B рекомбинантная) | G27: =IFERROR(__xludf.DUMMYFUNCTION("""COMPUTED_VALUE"""),"not in use") -> not in use | K27: =IFERROR(__xludf.DUMMYFUNCTION("""COMPUTED_VALUE"""),44712.0) -> 44712 | L27: =IFERROR(__xludf.DUMMYFUNCTION("""COMPUTED_VALUE"""),44712.0) -> 44712 | M27: =IFERROR(__xludf.DUMMYFUNCTION("""COMPUTED_VALUE"""),"нет") -> нет
A28: =IFERROR(__xludf.DUMMYFUNCTION("""COMPUTED_VALUE"""),27.0) -> 27 | B28: =IFERROR(__xludf.DUMMYFUNCTION("""COMPUTED_VALUE"""),"Cervarix") -> Cervarix | C28: =IFERROR(__xludf.DUMMYFUNCTION("""COMPUTED_VALUE"""),"https://grls.rosminzdrav.ru/Grls_View_v2.aspx?routingGuid=eb109c11-f04c-4753-b278-73a5bd064e47") -> https://grls.rosminzdrav.ru/Grls_View_v2.aspx?routingGuid=eb109c11-f04c-4753-b278-73a5bd064e47 | D28: =IFERROR(__xludf.DUMMYFUNCTION("""COMPUTED_VALUE"""),"Церварикс") -> Церварикс | E28: =IFERROR(__xludf.DUMMYFUNCTION("""COMPUTED_VALUE"""),"Церварикс®") -> Церварикс® | G28: =IFERROR(__xludf.DUMMYFUNCTION("""COMPUTED_VALUE"""),"in use") -> in use | K28: =IFERROR(__xludf.DUMMYFUNCTION("""COMPUTED_VALUE"""),44712.0) -> 44712 | L28: =IFERROR(__xludf.DUMMYFUNCTION("""COMPUTED_VALUE"""),45689.0) -> 45689 | M28: =IFERROR(__xludf.DUMMYFUNCTION("""COMPUTED_VALUE"""),"https://lk.regmed.ru/Register/GetPDFfromDAToken?Token=f88d9e07-3794-4fde-9c2d-fd91c377cc95") -> https://lk.regmed.ru/Register/GetPDFfromDAToken?Token=f88d9e07-3794-4fde-9c2d-fd91c377cc95
A29: =IFERROR(__xludf.DUMMYFUNCTION("""COMPUTED_VALUE"""),28.0) -> 28 | B29: =IFERROR(__xludf.DUMMYFUNCTION("""COMPUTED_VALUE"""),"Gardasil_4") -> Gardasil_4 | C29: =IFERROR(__xludf.DUMMYFUNCTION("""COMPUTED_VALUE"""),"https://grls.rosminzdrav.ru/Grls_View_v2.aspx?routingGuid=2ae3187f-3553-4a0f-953d-db66a9c16d23") -> https://grls.rosminzdrav.ru/Grls_View_v2.aspx?routingGuid=2ae3187f-3553-4a0f-953d-db66a9c16d23 | D29: =IFERROR(__xludf.DUMMYFUNCTION("""COMPUTED_VALUE"""),"Гардасил 4") -> Гардасил 4 | E29: =IFERROR(__xludf.DUMMYFUNCTION("""COMPUTED_VALUE"""),"Гардасил®") -> Гардасил® | F29: =IFERROR(__xludf.DUMMYFUNCTION("""COMPUTED_VALUE"""),"MSD") -> MSD | G29: =IFERROR(__xludf.DUMMYFUNCTION("""COMPUTED_VALUE"""),"in use") -> in use | H29: =IFERROR(__xludf.DUMMYFUNCTION("""COMPUTED_VALUE"""),"<p>4-валентная</p>") -> <p>4-валентная</p> | I29: =IFERROR(__xludf.DUMMYFUNCTION("""COMPUTED_VALUE"""),"4-валентная") -> 4-валентная | J29: =IFERROR(__xludf.DUMMYFUNCTION("""COMPUTED_VALUE"""),0.5) -> 0.5 | K29: =IFERROR(__xludf.DUMMYFUNCTION("""COMPUTED_VALUE"""),44712.0) -> 44712 | L29: =IFERROR(__xludf.DUMMYFUNCTION("""COMPUTED_VALUE"""),45689.0) -> 45689 | M29: =IFERROR(__xludf.DUMMYFUNCTION("""COMPUTED_VALUE"""),"https://lk.regmed.ru/Register/GetPDFfromDAToken?Token=ba26e648-28b3-4eac-b578-0748c8e03c4e") -> https://lk.regmed.ru/Register/GetPDFfromDAToken?Token=ba26e648-28b3-4eac-b578-0748c8e03c4e
A30: =IFERROR(__xludf.DUMMYFUNCTION("""COMPUTED_VALUE"""),29.0) -> 29 | B30: =IFERROR(__xludf.DUMMYFUNCTION("""COMPUTED_VALUE"""),"Sputnik") -> Sputnik | C30: =IFERROR(__xludf.DUMMYFUNCTION("""COMPUTED_VALUE"""),"https://grls.rosminzdrav.ru/Grls_View_v2.aspx?routingGuid=579be5e3-09cf-46b4-8238-f3087cd4e808") -> https://grls.rosminzdrav.ru/Grls_View_v2.aspx?routingGuid=579be5e3-09cf-46b4-8238-f3087cd4e808 | D30: =IFERROR(__xludf.DUMMYFUNCTION("""COMPUTED_VALUE"""),"Спутник V") -> Спутник V | E30: =IFERROR(__xludf.DUMMYFUNCTION("""COMPUTED_VALUE"""),"Гам-КОВИД-Вак Комбинированная векторная вакцина для профилактики коронавирусной инфекции, вызываемой вирусом SARS-CoV-2") -> Гам-КОВИД-Вак Комбинированная векторная вакцина для профилактики коронавирусной инфекции, вызываемой вирусом SARS-CoV-2 | F30: =IFERROR(__xludf.DUMMYFUNCTION("""COMPUTED_VALUE"""),"НИЦЭМ им. Н.Ф. Гамалеи") -> НИЦЭМ им. Н.Ф. Гамалеи | G30: =IFERROR(__xludf.DUMMYFUNCTION("""COMPUTED_VALUE"""),"in use") -> in use | J30: =IFERROR(__xludf.DUMMYFUNCTION("""COMPUTED_VALUE"""),0.5) -> 0.5 | K30: =IFERROR(__xludf.DUMMYFUNCTION("""COMPUTED_VALUE"""),44712.0) -> 44712 | L30: =IFERROR(__xludf.DUMMYFUNCTION("""COMPUTED_VALUE"""),45923.0) -> 45923 | M30: =IFERROR(__xludf.DUMMYFUNCTION("""COMPUTED_VALUE"""),"https://lk.regmed.ru/Register/GetPDFfromDAToken?Token=dc4e4486-14e8-430b-b506-5364c1e11fe7") -> https://lk.regmed.ru/Register/GetPDFfromDAToken?Token=dc4e4486-14e8-430b-b506-5364c1e11fe7
A31: =IFERROR(__xludf.DUMMYFUNCTION("""COMPUTED_VALUE"""),30.0) -> 30 | B31: =IFERROR(__xludf.DUMMYFUNCTION("""COMPUTED_VALUE"""),"Sputnik_Lyo") -> Sputnik_Lyo | C31: =IFERROR(__xludf.DUMMYFUNCTION("""COMPUTED_VALUE"""),"https://grls.rosminzdrav.ru/Grls_View_v2.aspx?routingGuid=ff05de13-f90b-475b-a47c-609c8a0539a7") -> https://grls.rosminzdrav.ru/Grls_View_v2.aspx?routingGuid=ff05de13-f90b-475b-a47c-609c8a0539a7 | D31: =IFERROR(__xludf.DUMMYFUNCTION("""COMPUTED_VALUE"""),"Спутник V (лиофилизат)") -> Спутник V (лиофилизат) | E31: =IFERROR(__xludf.DUMMYFUNCTION("""COMPUTED_VALUE"""),"Гам-КОВИД-Вак-Лио Комбинированная векторная вакцина для профилактики коронавирусной инфекции, вызываемой вирусом SARS-CoV-2") -> Гам-КОВИД-Вак-Лио Комбинированная векторная вакцина для профилактики коронавирусной инфекции, вызываемой вирусом SARS-CoV-2 | G31: =IFERROR(__xludf.DUMMYFUNCTION("""COMPUTED_VALUE"""),"not in use") -> not in use | K31: =IFERROR(__xludf.DUMMYFUNCTION("""COMPUTED_VALUE"""),44712.0) -> 44712 | L31: =IFERROR(__xludf.DUMMYFUNCTION("""COMPUTED_VALUE"""),44712.0) -> 44712 | M31: =IFERROR(__xludf.DUMMYFUNCTION("""COMPUTED_VALUE"""),"нет") -> нет
A32: =IFERROR(__xludf.DUMMYFUNCTION("""COMPUTED_VALUE"""),31.0) -> 31 | B32: =IFERROR(__xludf.DUMMYFUNCTION("""COMPUTED_VALUE"""),"EpiVacCorona") -> EpiVacCorona | C32: =IFERROR(__xludf.DUMMYFUNCTION("""COMPUTED_VALUE"""),"https://grls.rosminzdrav.ru/Grls_View_v2.aspx?routingGuid=fd7355d2-abfa-4846-99da-a1c5c6e8991a") -> https://grls.rosminzdrav.ru/Grls_View_v2.aspx?routingGuid=fd7355d2-abfa-4846-99da-a1c5c6e8991a | D32: =IFERROR(__xludf.DUMMYFUNCTION("""COMPUTED_VALUE"""),"ЭпиВакКорона") -> ЭпиВакКорона | E32: =IFERROR(__xludf.DUMMYFUNCTION("""COMPUTED_VALUE"""),"ЭпиВакКорона Вакцина на основе пептидных антигенов для профилактики COVID-19") -> ЭпиВакКорона Вакцина на основе пептидных антигенов для профилактики COVID-19 | F32: =IFERROR(__xludf.DUMMYFUNCTION("""COMPUTED_VALUE"""),"Вектор") -> Вектор | G32: =IFERROR(__xludf.DUMMYFUNCTION("""COMPUTED_VALUE"""),"not in use") -> not in use | J32: =IFERROR(__xludf.DUMMYFUNCTION("""COMPUTED_VALUE"""),0.5) -> 0.5 | K32: =IFERROR(__xludf.DUMMYFUNCTION("""COMPUTED_VALUE"""),44712.0) -> 44712 | L32: =IFERROR(__xludf.DUMMYFUNCTION("""COMPUTED_VALUE"""),45078.0) -> 45078 | M32: =IFERROR(__xludf.DUMMYFUNCTION("""COMPUTED_VALUE"""),"нет") -> нет
A33: =IFERROR(__xludf.DUMMYFUNCTION("""COMPUTED_VALUE"""),32.0) -> 32 | B33: =IFERROR(__xludf.DUMMYFUNCTION("""COMPUTED_VALUE"""),"Grippol_Microgen") -> Grippol_Microgen | C33: =IFERROR(__xludf.DUMMYFUNCTION("""COMPUTED_VALUE"""),"https://grls.rosminzdrav.ru/Grls_View_v2.aspx?routingGuid=70f8f0f0-7bac-41ec-a36d-51dcd6ebce84") -> https://grls.rosminzdrav.ru/Grls_View_v2.aspx?routingGuid=70f8f0f0-7bac-41ec-a36d-51dcd6ebce84 | D33: =IFERROR(__xludf.DUMMYFUNCTION("""COMPUTED_VALUE"""),"Гриппол (Микроген)") -> Гриппол (Микроген) | E33: =IFERROR(__xludf.DUMMYFUNCTION("""COMPUTED_VALUE"""),"Гриппол® Вакцина гриппозная тривалентная полимер-субъединичная жидкая") -> Гриппол® Вакцина гриппозная тривалентная полимер-субъединичная жидкая | F33: =IFERROR(__xludf.DUMMYFUNCTION("""COMPUTED_VALUE"""),"Микроген") -> Микроген | G33: =IFERROR(__xludf.DUMMYFUNCTION("""COMPUTED_VALUE"""),"not in use") -> not in use | K33: =IFERROR(__xludf.DUMMYFUNCTION("""COMPUTED_VALUE"""),44712.0) -> 44712 | L33: =IFERROR(__xludf.DUMMYFUNCTION("""COMPUTED_VALUE"""),44712.0) -> 44712 | M33: =IFERROR(__xludf.DUMMYFUNCTION("""COMPUTED_VALUE"""),"нет") -> нет
A34: =IFERROR(__xludf.DUMMYFUNCTION("""COMPUTED_VALUE"""),33.0) -> 33 | B34: =IFERROR(__xludf.DUMMYFUNCTION("""COMPUTED_VALUE"""),"Grippol_Petrovax") -> Grippol_Petrovax | C34: =IFERROR(__xludf.DUMMYFUNCTION("""COMPUTED_VALUE"""),"https://grls.rosminzdrav.ru/Grls_View_v2.aspx?routingGuid=ce700a9a-2b35-47e5-a73b-3cf65afee43b") -> https://grls.rosminzdrav.ru/Grls_View_v2.aspx?routingGuid=ce700a9a-2b35-47e5-a73b-3cf65afee43b | D34: =IFERROR(__xludf.DUMMYFUNCTION("""COMPUTED_VALUE"""),"Гриппол (Петровакс)") -> Гриппол (Петровакс) | E34: =IFERROR(__xludf.DUMMYFUNCTION("""COMPUTED_VALUE"""),"Гриппол® [Вакцина гриппозная тривалентная полимер-субъединичная жидкая]") -> Гриппол® [Вакцина гриппозная тривалентная полимер-субъединичная жидкая] | F34: =IFERROR(__xludf.DUMMYFUNCTION("""COMPUTED_VALUE"""),"Петровакс") -> Петровакс | G34: =IFERROR(__xludf.DUMMYFUNCTION("""COMPUTED_VALUE"""),"not in use") -> not in use | K34: =IFERROR(__xludf.DUMMYFUNCTION("""COMPUTED_VALUE"""),44712.0) -> 44712 | L34: =IFERROR(__xludf.DUMMYFUNCTION("""COMPUTED_VALUE"""),44712.0) -> 44712 | M34: =IFERROR(__xludf.DUMMYFUNCTION("""COMPUTED_VALUE"""),"нет") -> нет
A35: =IFERROR(__xludf.DUMMYFUNCTION("""COMPUTED_VALUE"""),34.0) -> 34 | B35: =IFERROR(__xludf.DUMMYFUNCTION("""COMPUTED_VALUE"""),"Grippol_plus_0_5") -> Grippol_plus_0_5 | C35: =IFERROR(__xludf.DUMMYFUNCTION("""COMPUTED_VALUE"""),"https://grls.rosminzdrav.ru/Grls_View_v2.aspx?routingGuid=907b510e-7f7f-46df-b43a-f6541b9871fc") -> https://grls.rosminzdrav.ru/Grls_View_v2.aspx?routingGuid=907b510e-7f7f-46df-b43a-f6541b9871fc | D35: =IFERROR(__xludf.DUMMYFUNCTION("""COMPUTED_VALUE"""),"Гриппол плюс 0,5 мл") -> Гриппол плюс 0,5 мл | E35: =IFERROR(__xludf.DUMMYFUNCTION("""COMPUTED_VALUE"""),"Гриппол® плюс [Вакцина гриппозная тривалентная инактивированная полимер-субъединичная]") -> Гриппол® плюс [Вакцина гриппозная тривалентная инактивированная полимер-субъединичная] | F35: =IFERROR(__xludf.DUMMYFUNCTION("""COMPUTED_VALUE"""),"Петровакс") -> Петровакс | G35: =IFERROR(__xludf.DUMMYFUNCTION("""COMPUTED_VALUE"""),"in use") -> in use | K35: =IFERROR(__xludf.DUMMYFUNCTION("""COMPUTED_VALUE"""),44712.0) -> 44712 | L35: =IFERROR(__xludf.DUMMYFUNCTION("""COMPUTED_VALUE"""),45689.0) -> 45689 | M35: =IFERROR(__xludf.DUMMYFUNCTION("""COMPUTED_VALUE"""),"https://lk.regmed.ru/Register/GetPDFfromDAToken?Token=8cc54647-279e-4b2f-82d7-b1ed3161d86a") -> https://lk.regmed.ru/Register/GetPDFfromDAToken?Token=8cc54647-279e-4b2f-82d7-b1ed3161d86a
A36: =IFERROR(__xludf.DUMMYFUNCTION("""COMPUTED_VALUE"""),35.0) -> 35 | B36: =IFERROR(__xludf.DUMMYFUNCTION("""COMPUTED_VALUE"""),"Sovigripp") -> Sovigripp | C36: =IFERROR(__xludf.DUMMYFUNCTION("""COMPUTED_VALUE"""),"https://grls.rosminzdrav.ru/Grls_View_v2.aspx?routingGuid=b287b682-550a-418f-8189-05dac16da4ae") -> https://grls.rosminzdrav.ru/Grls_View_v2.aspx?routingGuid=b287b682-550a-418f-8189-05dac16da4ae | D36: =IFERROR(__xludf.DUMMYFUNCTION("""COMPUTED_VALUE"""),"Совигрипп") -> Совигрипп | E36: =IFERROR(__xludf.DUMMYFUNCTION("""COMPUTED_VALUE"""),"СОВИГРИПП® Вакцина гриппозная инактивированная субъединичная") -> СОВИГРИПП® Вакцина гриппозная инактивированная субъединичная | F36: =IFERROR(__xludf.DUMMYFUNCTION("""COMPUTED_VALUE"""),"Микроген") -> Микроген | G36: =IFERROR(__xludf.DUMMYFUNCTION("""COMPUTED_VALUE"""),"in use") -> in use | K36: =IFERROR(__xludf.DUMMYFUNCTION("""COMPUTED_VALUE"""),44712.0) -> 44712 | L36: =IFERROR(__xludf.DUMMYFUNCTION("""COMPUTED_VALUE"""),45689.0) -> 45689 | M36: =IFERROR(__xludf.DUMMYFUNCTION("""COMPUTED_VALUE"""),"https://lk.regmed.ru/Register/GetPDFfromDAToken?Token=4d1562e5-05e7-405f-9673-b89a20ffd447") -> https://lk.regmed.ru/Register/GetPDFfromDAToken?Token=4d1562e5-05e7-405f-9673-b89a20ffd447
A37: =IFERROR(__xludf.DUMMYFUNCTION("""COMPUTED_VALUE"""),36.0) -> 36 | B37: =IFERROR(__xludf.DUMMYFUNCTION("""COMPUTED_VALUE"""),"Ultrix") -> Ultrix | C37: =IFERROR(__xludf.DUMMYFUNCTION("""COMPUTED_VALUE"""),"https://grls.rosminzdrav.ru/Grls_View_v2.aspx?routingGuid=b90698f2-e111-4450-b82c-5c3ca26a25f5") -> https://grls.rosminzdrav.ru/Grls_View_v2.aspx?routingGuid=b90698f2-e111-4450-b82c-5c3ca26a25f5 | D37: =IFERROR(__xludf.DUMMYFUNCTION("""COMPUTED_VALUE"""),"Ультрикс") -> Ультрикс | E37: =IFERROR(__xludf.DUMMYFUNCTION("""COMPUTED_VALUE"""),"Ультрикс® Вакцина гриппозная инактивированная расщепленная") -> Ультрикс® Вакцина гриппозная инактивированная расщепленная | F37: =IFERROR(__xludf.DUMMYFUNCTION("""COMPUTED_VALUE"""),"ФОРТ") -> ФОРТ | G37: =IFERROR(__xludf.DUMMYFUNCTION("""COMPUTED_VALUE"""),"not in use") -> not in use | K37: =IFERROR(__xludf.DUMMYFUNCTION("""COMPUTED_VALUE"""),44712.0) -> 44712 | L37: =IFERROR(__xludf.DUMMYFUNCTION("""COMPUTED_VALUE"""),45689.0) -> 45689 | M37: =IFERROR(__xludf.DUMMYFUNCTION("""COMPUTED_VALUE"""),"https://lk.regmed.ru/Register/GetPDFfromDAToken?Token=ebfed185-d787-4d31-8be8-d3cbc95b7794") -> https://lk.regmed.ru/Register/GetPDFfromDAToken?Token=ebfed185-d787-4d31-8be8-d3cbc95b7794
A38: =IFERROR(__xludf.DUMMYFUNCTION("""COMPUTED_VALUE"""),37.0) -> 37 | B38: =IFERROR(__xludf.DUMMYFUNCTION("""COMPUTED_VALUE"""),"Flu_M") -> Flu_M | C38: =IFERROR(__xludf.DUMMYFUNCTION("""COMPUTED_VALUE"""),"https://grls.rosminzdrav.ru/Grls_View_v2.aspx?routingGuid=e7496b1f-1be9-46a3-b43f-e1c83a5b6cc8") -> https://grls.rosminzdrav.ru/Grls_View_v2.aspx?routingGuid=e7496b1f-1be9-46a3-b43f-e1c83a5b6cc8 | D38: =IFERROR(__xludf.DUMMYFUNCTION("""COMPUTED_VALUE"""),"Флю-М") -> Флю-М | E38: =IFERROR(__xludf.DUMMYFUNCTION("""COMPUTED_VALUE"""),"Флю-М [Вакцина гриппозная инактивированная расщепленная]") -> Флю-М [Вакцина гриппозная инактивированная расщепленная] | F38: =IFERROR(__xludf.DUMMYFUNCTION("""COMPUTED_VALUE"""),"СПбНИИВС") -> СПбНИИВС | G38: =IFERROR(__xludf.DUMMYFUNCTION("""COMPUTED_VALUE"""),"in use") -> in use | K38: =IFERROR(__xludf.DUMMYFUNCTION("""COMPUTED_VALUE"""),44712.0) -> 44712 | L38: =IFERROR(__xludf.DUMMYFUNCTION("""COMPUTED_VALUE"""),46130.0) -> 46130 | M38: =IFERROR(__xludf.DUMMYFUNCTION("""COMPUTED_VALUE"""),"нет") -> нет
A39: =IFERROR(__xludf.DUMMYFUNCTION("""COMPUTED_VALUE"""),38.0) -> 38 | B39: =IFERROR(__xludf.DUMMYFUNCTION("""COMPUTED_VALUE"""),"Vaxigrip") -> Vaxigrip | C39: =IFERROR(__xludf.DUMMYFUNCTION("""COMPUTED_VALUE"""),"https://grls.rosminzdrav.ru/Grls_View_v2.aspx?routingGuid=34537f7c-cc43 – 45ef-bc9a-9820641bf718") -> https://grls.rosminzdrav.ru/Grls_View_v2.aspx?routingGuid=34537f7c-cc43 – 45ef-bc9a-9820641bf718 | D39: =IFERROR(__xludf.DUMMYFUNCTION("""COMPUTED_VALUE"""),"Ваксигрип") -> Ваксигрип | E39: =IFERROR(__xludf.DUMMYFUNCTION("""COMPUTED_VALUE"""),"Ваксигрип® (инактивированная сплит-вакцина для профилактики гриппа)") -> Ваксигрип® (инактивированная сплит-вакцина для профилактики гриппа) | G39: =IFERROR(__xludf.DUMMYFUNCTION("""COMPUTED_VALUE"""),"not in use") -> not in use | K39: =IFERROR(__xludf.DUMMYFUNCTION("""COMPUTED_VALUE"""),44712.0) -> 44712 | L39: =IFERROR(__xludf.DUMMYFUNCTION("""COMPUTED_VALUE"""),45078.0) -> 45078 | M39: =IFERROR(__xludf.DUMMYFUNCTION("""COMPUTED_VALUE"""),"нет") -> нет
A40: =IFERROR(__xludf.DUMMYFUNCTION("""COMPUTED_VALUE"""),39.0) -> 39 | B40: =IFERROR(__xludf.DUMMYFUNCTION("""COMPUTED_VALUE"""),"Influvac") -> Influvac | C40: =IFERROR(__xludf.DUMMYFUNCTION("""COMPUTED_VALUE"""),"https://grls.rosminzdrav.ru/Grls_View_v2.aspx?routingGuid=f0e5ea62-1cea-4427-923d-201a87349492") -> https://grls.rosminzdrav.ru/Grls_View_v2.aspx?routingGuid=f0e5ea62-1cea-4427-923d-201a87349492 | D40: =IFERROR(__xludf.DUMMYFUNCTION("""COMPUTED_VALUE"""),"Инфлювак") -> Инфлювак | E40: =IFERROR(__xludf.DUMMYFUNCTION("""COMPUTED_VALUE"""),"Инфлювак® (вакцина гриппозная субъединичная инактивированная)") -> Инфлювак® (вакцина гриппозная субъединичная инактивированная) | G40: =IFERROR(__xludf.DUMMYFUNCTION("""COMPUTED_VALUE"""),"in use") -> in use | K40: =IFERROR(__xludf.DUMMYFUNCTION("""COMPUTED_VALUE"""),44712.0) -> 44712 | L40: =IFERROR(__xludf.DUMMYFUNCTION("""COMPUTED_VALUE"""),46130.0) -> 46130 | M40: =IFERROR(__xludf.DUMMYFUNCTION("""COMPUTED_VALUE"""),"есть") -> есть
...

Sheet ingredients_text
A1: vaccine_id | B1: code_name | C1: ingredients_text_w/o_html | D1: ingredients_text_html | E1: ingredients_date | F1: ingredients_view_number | G1: ingredients_version | H1: ingredients_version_link | I1: creation_date | J1: update_date | K1: comment
A2: 1 | B2: =VLOOKUP(A2,vaccines!A:B,2) -> BCG_Microgen | C2: 1 доза (0,1 мл) содержит: Действующее вещество: микробные клетки Mycobacterium bovis BCG-I — 0,05 мг*. Полный перечень вспомогательных веществ приведен в разделе 6.1. Препарат не содержит консервантов и антибиотиков. Выпускается в комплекте с растворителем — натрия хлорид растворитель для приготовления лекарственных форм для инъекций 0,9 %. * расчетное содержание в 1 дозе. 6.1. Перечень вспомогательных веществ Лиофилизат: • Натрия глутамата моногидрат. | D2: <p>1&nbsp;доза (0,1&nbsp;мл) содержит:<br><br> Действующее вещество: микробные клетки <i>Mycobacterium bovis BCG-I</i> — 0,05&nbsp;мг*.<br> Полный перечень вспомогательных веществ приведен в разделе&nbsp;6.1.<br> Препарат не содержит консервантов и антибиотиков.<br> Выпускается в комплекте с растворителем — натрия хлорид растворитель для приготовления лекарственных форм для инъекций 0,9&nbsp;%.<br><br> *&nbsp;расчетное содержание в 1&nbsp;дозе.<br><br> <b>6.1.&nbsp;Перечень вспомогательных веществ</b><br><br> <i>Лиофилизат:</i> <ul><li>Натрия глутамата моногидрат.</li></ul></p> | E2: 45461 | H2: https://lk.regmed.ru/Register/GetPDFfromDA?ID=1597322951 | I2: 45105 | J2: 45517 | K2: добавлено Елена Савинова
A3: 2 | B3: =VLOOKUP(A3,vaccines!A:B,2) -> BCG_M_Microgen | C3: 1 доза (0,1 мл) содержит: Действующее вещество: микробные клетки Mycobacterium bovis BCG-I — 0,025 мг*. Полный перечень вспомогательных веществ приведен в разделе 6.1. Препарат не содержит консервантов и антибиотиков. Выпускается в комплекте с растворителем — натрия хлорид растворитель для приготовления лекарственных форм для инъекций 0,9 %. * расчетное содержание в 1 дозе. 6.1. Перечень вспомогательных веществ • Натрия глутамата моногидрат. | D3: <p>1&nbsp;доза (0,1&nbsp;мл) содержит:<br><br> Действующее вещество: микробные клетки <i>Mycobacterium bovis BCG-I</i> — 0,025&nbsp;мг*.<br> Полный перечень вспомогательных веществ приведен в разделе&nbsp;6.1.<br> Препарат не содержит консервантов и антибиотиков.<br> Выпускается в комплекте с растворителем — натрия хлорид растворитель для приготовления лекарственных форм для инъекций 0,9&nbsp;%.<br><br> *&nbsp;расчетное содержание в 1&nbsp;дозе.<br><br> <b>6.1.&nbsp;Перечень вспомогательных веществ</b> <ul><li>Натрия глутамата моногидрат.</li></ul></p> | E3: 45461 | H3: https://lk.regmed.ru/Register/GetPDFfromDA?ID=1597318981 | I3: 45107 | J3: 45517 | K3: проверено Елена Савинова
A4: 3 | B4: =VLOOKUP(A4,vaccines!A:B,2) -> BCG_Gamaleya | C4: В одной дозе содержится: • 0,05 мг Микобактерий вакцинного штамма Mycobacterium bovis, субштамм BCG-1 (Russia). Перечень вспомогательных веществ: • Стабилизатор — натрия глутамат моногидрат — не более 0,3 мг; • Раствор натрия хлорида 0,9 % для инъекций — до 0,1 мл. | D4: <p>В одной дозе содержится: <ul><li>0,05&nbsp;мг Микобактерий вакцинного штамма <i>Mycobacterium bovis</i>, субштамм BCG-1 (Russia).</li></ul> Перечень вспомогательных веществ: <ul><li>Стабилизатор — натрия глутамат моногидрат — не более 0,3&nbsp;мг;</li> <li>Раствор натрия хлорида 0,9&nbsp;% для инъекций — до 0,1&nbsp;мл.</li></ul></p> | E4: 45769 | F4: 1 | G4: 0 | H4: https://grls.rosminzdrav.ru/InstrImg/2025/05/19/1517351/3bec22d2-65bc-4a94-9482-413901e57760.pdf | I4: 45108 | J4: 45801
